Workbook

Sheet Trends
A1: Week 2 (2015-2024)
A2: Win percentage for home teams favored from -6.5 to -5.5 in week 2: 57.14% (12 of 21) Cover percentage for home teams favored from -6.5 to -5.5 in week 2: 19.05% (4 of 21) | Z2: PHI, WAS
A3: Win percentage for road favorites in week 2 (2021-2024): 66.67% (16 of 24) | Z3: DEN
Z5: LAC, CLE, NO, NYJ, ATL, SEA, CHI (Teams to FADE week 1)
Z6: KC, CIN, ARI, PIT, TB, SF, MIN
E13: Opp_pYds | F13: Tm_pYds
E14: Opp_pTD | F14: Tm_pTD | J14: season
E15: Opp_rYds | F15: Tm_rYds
E16: Opp_rTD | F16: Tm_rTD
E17: Opp_rY/A | F17: Tm_rY/A
R33: Aaron Rodgers | S33: 7 | V33: =SUM(S33:S57) -> 165
R34: Baker Mayfield | S34: 8
R35: Bo Nix | S35: 9
R36: Brock Purdy | S36: 12
R37: Caleb Williams | S37: 10
R38: Davis Mills | S38: 4
R39: JJ McCarthy | S39: 10
R40: Jacoby Brissett | S40: 6
R41: Jameis Winston | S41: 15
R42: Joe Flacco | S42: 11
R43: Jordan Love | S43: 8
R44: Josh Allen | S44: 12
R45: Justin Herbert | S45: 12
... R51: Lawerence | S51: 3

Sheet Model Predictions
A1: Week | B1: Game | C1: Away | D1: Home | E1: Spread | F1: Total | G1: Over_Pred | H1: Under_Pred | I1: Cover_Pred | J1: Cover_Pred_Model | K1: Opp_Pts_Pred | L1: Tm_Pts_Pred | M1: Total_Pred | N1: Over_Prob | O1: Under_Prob | P1: Cover_Prob | Q1: Act_Opp_Pts | R1: Act_Tm_Pts | S1: Act_Total | T1: Cover | U1: Total_Kneibors | V1: Home_PRED_COVER | W1: Error_Spread_Opp | X1: Error_Spread_Tm | Y1: ABS_Spread_Opp | Z1: ABS_Spread_Tm | AA1: Squared_Error_Opp | AB1: Squared_Error_Tm | AC1: %_Error_Opp | AD1: %_Error_Tm | AE1: Mean_Absolute_Error_Opp | AF1: Mean_Absolute_Error_Tm | AG1: Mean_Squared_Error_Opp | AH1: Mean_Squared_Error_Tm | AI1: Root_Mean_Squared_Error_Opp | AJ1: Root_Mean_Squared_Error_Tm | AK1: STDEV_Opp | AL1: STDEV_Tm | AN1: Home TeamCover % | AO1: Total_Kneibors % | AP1: Home PRED_COVER
A2: 1 | B2: dal @ phi | C2: =TRIM(LEFT(B2, FIND("@", B2)-1)) -> dal | D2: =TRIM(MID(B2, FIND("@", B2)+1, LEN(B2))) -> phi | E2: -8.5 | F2: 48 | G2: Over | H2: Not Under | I2: 0 | J2: No Cover | K2: 26 | L2: 30 | M2: 56 | N2: 79 | O2: 21 | P2: 33 | Q2: 20 | R2: 24 | S2: =Q2+R2 -> 44 | T2: =IF(R2+E2>Q2,1,0) -> 0 | U2: =IF(G2="Over", IF(F2<S2, 1, 0), IF(F2>S2, 1, 0)) -> 0 | V2: =IF(AND(J2="No Cover", T2=0), 1, IF(AND(J2="Cover", T2=1), 1, 0)) -> 1 | W2: =Q2-K2 -> -6 | X2: =R2-L2 -> -6 | Y2: =ABS(W2) -> 6 | Z2: =ABS(X2) -> 6 | AA2: =(W2)^2 -> 36 | AB2: =(X2)^2 -> 36 | AC2: =ABS(W2)/Q2 -> 0.3 | AD2: =ABS(X2)/R2 -> 0.25 | AE2: =AVERAGE(Y:Y) -> 7.6158537 | AF2: =AVERAGE(Z:Z) -> 8.1158537 | AG2: =AVERAGE(AA:AA) -> 89.762195 | AH2: =AVERAGE(AB:AB) -> 104.75 | AI2: =SQRT(AG2) -> 9.4742913 | AJ2: =SQRT(AH2) -> 10.234745 | AK2: =_xlfn.STDEV.P(W:W) -> 9.4352008 | AL2: =_xlfn.STDEV.P(X:X) -> 10.197534 | AN2: =COUNTIF(T:T,1)/(COUNTIF(T:T,1)+COUNTIF(T:T,0)) -> 0.51219512 | AO2: =COUNTIF(U:U,1)/(COUNTIF(U:U,1)+COUNTIF(U:U,0)) -> 0.56097561 | AP2: =COUNTIF(V:V,1)/(COUNTIF(V:V,1)+COUNTIF(V:V,0)) -> 0.47560976
A3: 1 | B3: kan @ sdg | C3: =TRIM(LEFT(B3, FIND("@", B3)-1)) -> kan | D3: =TRIM(MID(B3, FIND("@", B3)+1, LEN(B3))) -> sdg | E3: 3 | F3: 47.5 | G3: Over | H3: Not Under | I3: 0 | J3: No Cover | K3: 29 | L3: 23 | M3: 52 | N3: 67 | O3: 33 | P3: 38 | Q3: 21 | R3: 27 | S3: =Q3+R3 -> 48 | T3: =IF(R3+E3>Q3,1,0) -> 1 | U3: =IF(G3="Over", IF(F3<S3, 1, 0), IF(F3>S3, 1, 0)) -> 1 | V3: =IF(AND(J3="No Cover", T3=0), 1, IF(AND(J3="Cover", T3=1), 1, 0)) -> 0 | W3: =Q3-K3 -> -8 | X3: =R3-L3 -> 4 | Y3: =ABS(W3) -> 8 | Z3: =ABS(X3) -> 4 | AA3: =(W3)^2 -> 64 | AB3: =(X3)^2 -> 16 | AC3: =ABS(W3)/Q3 -> 0.38095238 | AD3: =ABS(X3)/R3 -> 0.14814815
A4: 1 | B4: tam @ atl | C4: =TRIM(LEFT(B4, FIND("@", B4)-1)) -> tam | D4: =TRIM(MID(B4, FIND("@", B4)+1, LEN(B4))) -> atl | E4: 1 | F4: 47 | G4: Not Over | H4: Under | I4: 1 | J4: Cover | K4: 18 | L4: 26 | M4: 44 | N4: 38 | O4: 62 | P4: 82 | Q4: 23 | R4: 20 | S4: =Q4+R4 -> 43 | T4: =IF(R4+E4>Q4,1,0) -> 0 | U4: =IF(G4="Over", IF(F4<S4, 1, 0), IF(F4>S4, 1, 0)) -> 1 | V4: =IF(AND(J4="No Cover", T4=0), 1, IF(AND(J4="Cover", T4=1), 1, 0)) -> 0 | W4: =Q4-K4 -> 5 | X4: =R4-L4 -> -6 | Y4: =ABS(W4) -> 5 | Z4: =ABS(X4) -> 6 | AA4: =(W4)^2 -> 25 | AB4: =(X4)^2 -> 36 | AC4: =ABS(W4)/Q4 -> 0.2173913 | AD4: =ABS(X4)/R4 -> 0.3
A5: 1 | B5: cin @ cle | C5: =TRIM(LEFT(B5, FIND("@", B5)-1)) -> cin | D5: =TRIM(MID(B5, FIND("@", B5)+1, LEN(B5))) -> cle | E5: 5 | F5: 48 | G5: Over | H5: Not Under | I5: 0 | J5: No Cover | K5: 30 | L5: 24 | M5: 54 | N5: 73 | O5: 27 | P5: 47 | Q5: 17 | R5: 16 | S5: =Q5+R5 -> 33 | T5: =IF(R5+E5>Q5,1,0) -> 1 | U5: =IF(G5="Over", IF(F5<S5, 1, 0), IF(F5>S5, 1, 0)) -> 0 | V5: =IF(AND(J5="No Cover", T5=0), 1, IF(AND(J5="Cover", T5=1), 1, 0)) -> 0 | W5: =Q5-K5 -> -13 | X5: =R5-L5 -> -8 | Y5: =ABS(W5) -> 13 | Z5: =ABS(X5) -> 8 | AA5: =(W5)^2 -> 169 | AB5: =(X5)^2 -> 64 | AC5: =ABS(W5)/Q5 -> 0.76470588 | AD5: =ABS(X5)/R5 -> 0.5
A6: 1 | B6: mia @ clt | C6: =TRIM(LEFT(B6, FIND("@", B6)-1)) -> mia | D6: =TRIM(MID(B6, FIND("@", B6)+1, LEN(B6))) -> clt | E6: -1 | F6: 46.5 | G6: Not Over | H6: Under | I6: 0 | J6: No Cover | K6: 28 | L6: 22 | M6: 50 | N6: 64 | O6: 36 | P6: 24 | Q6: 8 | R6: 33 | S6: =Q6+R6 -> 41 | T6: =IF(R6+E6>Q6,1,0) -> 1 | U6: =IF(G6="Over", IF(F6<S6, 1, 0), IF(F6>S6, 1, 0)) -> 1 | V6: =IF(AND(J6="No Cover", T6=0), 1, IF(AND(J6="Cover", T6=1), 1, 0)) -> 0 | W6: =Q6-K6 -> -20 | X6: =R6-L6 -> 11 | Y6: =ABS(W6) -> 20 | Z6: =ABS(X6) -> 11 | AA6: =(W6)^2 -> 400 | AB6: =(X6)^2 -> 121 | AC6: =ABS(W6)/Q6 -> 2.5 | AD6: =ABS(X6)/R6 -> 0.33333333
A7: 1 | B7: car @ jax | C7: =TRIM(LEFT(B7, FIND("@", B7)-1)) -> car | D7: =TRIM(MID(B7, FIND("@", B7)+1, LEN(B7))) -> jax | E7: -4 | F7: 46.5 | G7: Over | H7: Not Under | I7: 1 | J7: Cover | K7: 21 | L7: 31 | M7: 52 | N7: 70 | O7: 30 | P7: 73 | Q7: 10 | R7: 26 | S7: =Q7+R7 -> 36 | T7: =IF(R7+E7>Q7,1,0) -> 1 | U7: =IF(G7="Over", IF(F7<S7, 1, 0), IF(F7>S7, 1, 0)) -> 0 | V7: =IF(AND(J7="No Cover", T7=0), 1, IF(AND(J7="Cover", T7=1), 1, 0)) -> 1 | W7: =Q7-K7 -> -11 | X7: =R7-L7 -> -5 | Y7: =ABS(W7) -> 11 | Z7: =ABS(X7) -> 5 | AA7: =(W7)^2 -> 121 | AB7: =(X7)^2 -> 25 | AC7: =ABS(W7)/Q7 -> 1.1 | AD7: =ABS(X7)/R7 -> 0.19230769
A8: 1 | B8: crd @ nor | C8: =TRIM(LEFT(B8, FIND("@", B8)-1)) -> crd | D8: =TRIM(MID(B8, FIND("@", B8)+1, LEN(B8))) -> nor | E8: 6.5 | F8: 44 | G8: Not Over | H8: Under | I8: 0 | J8: No Cover | K8: 26 | L8: 18 | M8: 44 | N8: 49 | O8: 51 | P8: 44 | Q8: 20 | R8: 13 | S8: =Q8+R8 -> 33 | T8: =IF(R8+E8>Q8,1,0) -> 0 | U8: =IF(G8="Over", IF(F8<S8, 1, 0), IF(F8>S8, 1, 0)) -> 1 | V8: =IF(AND(J8="No Cover", T8=0), 1, IF(AND(J8="Cover", T8=1), 1, 0)) -> 1 | W8: =Q8-K8 -> -6 | X8: =R8-L8 -> -5 | Y8: =ABS(W8) -> 6 | Z8: =ABS(X8) -> 5 | AA8: =(W8)^2 -> 36 | AB8: =(X8)^2 -> 25 | AC8: =ABS(W8)/Q8 -> 0.3 | AD8: =ABS(X8)/R8 -> 0.38461538
A9: 1 | B9: rai @ nwe | C9: =TRIM(LEFT(B9, FIND("@", B9)-1)) -> rai | D9: =TRIM(MID(B9, FIND("@", B9)+1, LEN(B9))) -> nwe | E9: -2.5 | F9: 44 | G9: Not Over | H9: Under | I9: 1 | J9: Cover | K9: 22 | L9: 28 | M9: 50 | N9: 73 | O9: 27 | P9: 65 | Q9: 20 | R9: 13 | S9: =Q9+R9 -> 33 | T9: =IF(R9+E9>Q9,1,0) -> 0 | U9: =IF(G9="Over", IF(F9<S9, 1, 0), IF(F9>S9, 1, 0)) -> 1 | V9: =IF(AND(J9="No Cover", T9=0), 1, IF(AND(J9="Cover", T9=1), 1, 0)) -> 0 | W9: =Q9-K9 -> -2 | X9: =R9-L9 -> -15 | Y9: =ABS(W9) -> 2 | Z9: =ABS(X9) -> 15 | AA9: =(W9)^2 -> 4 | AB9: =(X9)^2 -> 225 | AC9: =ABS(W9)/Q9 -> 0.1 | AD9: =ABS(X9)/R9 -> 1.1538462
A10: 1 | B10: pit @ nyj | C10: =TRIM(LEFT(B10, FIND("@", B10)-1)) -> pit | D10: =TRIM(MID(B10, FIND("@", B10)+1, LEN(B10))) -> nyj | E10: 3 | F10: 38 | G10: Not Over | H10: Under | I10: 0 | J10: No Cover | K10: 21 | L10: 14 | M10: 35 | N10: 38 | O10: 62 | P10: 34 | Q10: 34 | R10: 32 | S10: =Q10+R10 -> 66 | T10: =IF(R10+E10>Q10,1,0) -> 1 | U10: =IF(G10="Over", IF(F10<S10, 1, 0), IF(F10>S10, 1, 0)) -> 0 | V10: =IF(AND(J10="No Cover", T10=0), 1, IF(AND(J10="Cover", T10=1), 1, 0)) -> 0 | W10: =Q10-K10 -> 13 | X10: =R10-L10 -> 18 | Y10: =ABS(W10) -> 13 | Z10: =ABS(X10) -> 18 | AA10: =(W10)^2 -> 169 | AB10: =(X10)^2 -> 324 | AC10: =ABS(W10)/Q10 -> 0.38235294 | AD10: =ABS(X10)/R10 -> 0.5625
A11: 1 | B11: nyg @ was | C11: =TRIM(LEFT(B11, FIND("@", B11)-1)) -> nyg | D11: =TRIM(MID(B11, FIND("@", B11)+1, LEN(B11))) -> was | E11: -6 | F11: 45.5 | G11: Not Over | H11: Under | I11: 0 | J11: No Cover | K11: 21 | L11: 26 | M11: 47 | N11: 55 | O11: 45 | P11: 46 | Q11: 6 | R11: 21 | S11: =Q11+R11 -> 27 | T11: =IF(R11+E11>Q11,1,0) -> 1 | U11: =IF(G11="Over", IF(F11<S11, 1, 0), IF(F11>S11, 1, 0)) -> 1 | V11: =IF(AND(J11="No Cover", T11=0), 1, IF(AND(J11="Cover", T11=1), 1, 0)) -> 0 | W11: =Q11-K11 -> -15 | X11: =R11-L11 -> -5 | Y11: =ABS(W11) -> 15 | Z11: =ABS(X11) -> 5 | AA11: =(W11)^2 -> 225 | AB11: =(X11)^2 -> 25 | AC11: =ABS(W11)/Q11 -> 2.5 | AD11: =ABS(X11)/R11 -> 0.23809524
A12: 1 | B12: oti @ den | C12: =TRIM(LEFT(B12, FIND("@", B12)-1)) -> oti | D12: =TRIM(MID(B12, FIND("@", B12)+1, LEN(B12))) -> den | E12: -9 | F12: 43 | G12: Not Over | H12: Under | I12: 0 | J12: No Cover | K12: 17 | L12: 26 | M12: 43 | N12: 49 | O12: 51 | P12: 50 | Q12: 12 | R12: 20 | S12: =Q12+R12 -> 32 | T12: =IF(R12+E12>Q12,1,0) -> 0 | U12: =IF(G12="Over", IF(F12<S12, 1, 0), IF(F12>S12, 1, 0)) -> 1 | V12: =IF(AND(J12="No Cover", T12=0), 1, IF(AND(J12="Cover", T12=1), 1, 0)) -> 1 | W12: =Q12-K12 -> -5 | X12: =R12-L12 -> -6 | Y12: =ABS(W12) -> 5 | Z12: =ABS(X12) -> 6 | AA12: =(W12)^2 -> 25 | AB12: =(X12)^2 -> 36 | AC12: =ABS(W12)/Q12 -> 0.41666667 | AD12: =ABS(X12)/R12 -> 0.3
A13: 1 | B13: sfo @ sea | C13: =TRIM(LEFT(B13, FIND("@", B13)-1)) -> sfo | D13: =TRIM(MID(B13, FIND("@", B13)+1, LEN(B13))) -> sea | E13: 1 | F13: 43.5 | G13: Not Over | H13: Under | I13: 0 | J13: Cover | K13: 22 | L13: 22 | M13: 44 | N13: 51 | O13: 49 | P13: 54 | Q13: 17 | R13: 13 | S13: =Q13+R13 -> 30 | T13: =IF(R13+E13>Q13,1,0) -> 0 | U13: =IF(G13="Over", IF(F13<S13, 1, 0), IF(F13>S13, 1, 0)) -> 1 | V13: =IF(AND(J13="No Cover", T13=0), 1, IF(AND(J13="Cover", T13=1), 1, 0)) -> 0 | W13: =Q13-K13 -> -5 | X13: =R13-L13 -> -9 | Y13: =ABS(W13) -> 5 | Z13: =ABS(X13) -> 9 | AA13: =(W13)^2 -> 25 | AB13: =(X13)^2 -> 81 | AC13: =ABS(W13)/Q13 -> 0.29411765 | AD13: =ABS(X13)/R13 -> 0.69230769
A14: 1 | B14: det @ gnb | C14: =TRIM(LEFT(B14, FIND("@", B14)-1)) -> det | D14: =TRIM(MID(B14, FIND("@", B14)+1, LEN(B14))) -> gnb | E14: -2 | F14: 47.5 | G14: Not Over | H14: Under | I14: 0 | J14: No Cover | K14: 23 | L14: 19 | M14: 42 | N14: 29 | O14: 71 | P14: 27 | Q14: 13 | R14: 27 | S14: =Q14+R14 -> 40 | T14: =IF(R14+E14>Q14,1,0) -> 1 | U14: =IF(G14="Over", IF(F14<S14, 1, 0), IF(F14>S14, 1, 0)) -> 1 | V14: =IF(AND(J14="No Cover", T14=0), 1, IF(AND(J14="Cover", T14=1), 1, 0)) -> 0 | W14: =Q14-K14 -> -10 | X14: =R14-L14 -> 8 | Y14: =ABS(W14) -> 10 | Z14: =ABS(X14) -> 8 | AA14: =(W14)^2 -> 100 | AB14: =(X14)^2 -> 64 | AC14: =ABS(W14)/Q14 -> 0.76923077 | AD14: =ABS(X14)/R14 -> 0.2962963
... A165: 11 | B165: dal @ rai | C165: =TRIM(LEFT(B165, FIND("@", B165)-1)) -> dal | D165: =TRIM(MID(B165, FIND("@", B165)+1, LEN(B165))) -> rai | E165: 3.5 | F165: 50.5 | G165: Over | H165: Not Under | I165: 0 | J165: No Cover | K165: 33 | L165: 26 | M165: 59 | N165: 81 | O165: 19 | P165: 36 | Q165: 33 | R165: 16 | S165: =Q165+R165 -> 49 | T165: =IF(R165+E165>Q165,1,0) -> 0 | U165: =IF(G165="Over", IF(F165<S165, 1, 0), IF(F165>S165, 1, 0)) -> 0 | V165: =IF(AND(J165="No Cover", T165=0), 1, IF(AND(J165="Cover", T165=1), 1, 0)) -> 1 | W165: =Q165-K165 -> 0 | X165: =R165-L165 -> -10 | Y165: =ABS(W165) -> 0 | Z165: =ABS(X165) -> 10 | AA165: =(W165)^2 -> 0 | AB165: =(X165)^2 -> 100 | AC165: =ABS(W165)/Q165 -> 0 | AD165: =ABS(X165)/R165 -> 0.625
A166: 12 | B166: buf @ htx | C166: =TRIM(LEFT(B166, FIND("@", B166)-1)) -> buf | D166: =TRIM(MID(B166, FIND("@", B166)+1, LEN(B166))) -> htx | E166: 5.5 | F166: 43.5 | G166: Not Over | H166: Under | I166: 0 | J166: No Cover | K166: 28 | L166: 18 | M166: 46 | N166: 60 | O166: 40 | P166: 33
A167: 12 | B167: sea @ oti | C167: =TRIM(LEFT(B167, FIND("@", B167)-1)) -> sea | D167: =TRIM(MID(B167, FIND("@", B167)+1, LEN(B167))) -> oti | E167: 13.5 | F167: 40.5 | G167: Over | H167: Not Under | I167: 0 | J167: Cover | K167: 24 | L167: 15 | M167: 39 | N167: 44 | O167: 56 | P167: 68
A168: 12 | B168: nyg @ det | C168: =TRIM(LEFT(B168, FIND("@", B168)-1)) -> nyg | D168: =TRIM(MID(B168, FIND("@", B168)+1, LEN(B168))) -> det | E168: -10.5 | F168: 49.5 | G168: Over | H168: Not Under | I168: 1 | J168: No Cover | K168: 22 | L168: 31 | M168: 53 | N168: 63 | O168: 37 | P168: 45
A169: 12 | B169: nyj @ rav | C169: =TRIM(LEFT(B169, FIND("@", B169)-1)) -> nyj | D169: =TRIM(MID(B169, FIND("@", B169)+1, LEN(B169))) -> rav | E169: -13.5 | F169: 44.5 | G169: Over | H169: Not Under | I169: 0 | J169: No Cover | K169: 18 | L169: 28 | M169: 46 | N169: 56 | O169: 44 | P169: 37
A170: 12 | B170: pit @ chi | C170: =TRIM(LEFT(B170, FIND("@", B170)-1)) -> pit | D170: =TRIM(MID(B170, FIND("@", B170)+1, LEN(B170))) -> chi | E170: -3 | F170: 45 | G170: Not Over | H170: Under | I170: 0 | J170: No Cover | K170: 22 | L170: 21 | M170: 43 | N170: 42 | O170: 58 | P170: 34
A171: 12 | B171: nwe @ cin | C171: =TRIM(LEFT(B171, FIND("@", B171)-1)) -> nwe | D171: =TRIM(MID(B171, FIND("@", B171)+1, LEN(B171))) -> cin | E171: 7.5 | F171: 49.5 | G171: Over | H171: Not Under | I171: 0 | J171: No Cover | K171: 34 | L171: 18 | M171: 52 | N171: 60 | O171: 40 | P171: 20
A172: 12 | B172: clt @ kan | C172: =TRIM(LEFT(B172, FIND("@", B172)-1)) -> clt | D172: =TRIM(MID(B172, FIND("@", B172)+1, LEN(B172))) -> kan | E172: -3 | F172: 50.5 | G172: Not Over | H172: Under | I172: 0 | J172: No Cover | K172: 24 | L172: 26 | M172: 50 | N172: 49 | O172: 51 | P172: 47
A173: 12 | B173: min @ gnb | C173: =TRIM(LEFT(B173, FIND("@", B173)-1)) -> min | D173: =TRIM(MID(B173, FIND("@", B173)+1, LEN(B173))) -> gnb | E173: -6.5 | F173: 41 | G173: Not Over | H173: Under | I173: 0 | J173: No Cover | K173: 18 | L173: 21 | M173: 39 | N173: 43 | O173: 57 | P173: 36
A174: 12 | B174: cle @ rai | C174: =TRIM(LEFT(B174, FIND("@", B174)-1)) -> cle | D174: =TRIM(MID(B174, FIND("@", B174)+1, LEN(B174))) -> rai | E174: -3 | F174: 37 | G174: Over | H174: Not Under | I174: 1 | J174: Cover | K174: 18 | L174: 22 | M174: 40 | N174: 61 | O174: 39 | P174: 54
A175: 12 | B175: jax @ crd | C175: =TRIM(LEFT(B175, FIND("@", B175)-1)) -> jax | D175: =TRIM(MID(B175, FIND("@", B175)+1, LEN(B175))) -> crd | E175: 2.5 | F175: 47.5 | G175: Not Over | H175: Under | I175: 0 | J175: No Cover | K175: 25 | L175: 19 | M175: 44 | N175: 37 | O175: 63 | P175: 36
A176: 12 | B176: atl @ nor | C176: =TRIM(LEFT(B176, FIND("@", B176)-1)) -> atl | D176: =TRIM(MID(B176, FIND("@", B176)+1, LEN(B176))) -> nor | E176: -1.5 | F176: 39.5 | G176: Over | H176: Not Under | I176: 0 | J176: No Cover | K176: 27 | L176: 17 | M176: 44 | N176: 68 | O176: 32 | P176: 12
A177: 12 | B177: phi @ dal | C177: =TRIM(LEFT(B177, FIND("@", B177)-1)) -> phi | D177: =TRIM(MID(B177, FIND("@", B177)+1, LEN(B177))) -> dal | E177: 3.5 | F177: 49.5 | G177: Not Over | H177: Under | I177: 1 | J177: No Cover | K177: 26 | L177: 22 | M177: 48 | N177: 44 | O177: 56 | P177: 48
... A179: 12 | B179: car @ sfo | C179: =TRIM(LEFT(B179, FIND("@", B179)-1)) -> car | D179: =TRIM(MID(B179, FIND("@", B179)+1, LEN(B179))) -> sfo | E179: -7 | F179: 48.5 | G179: Not Over | H179: Under | I179: 0 | J179: Cover | K179: 21 | L179: 30 | M179: 51 | N179: 60 | O179: 40 | P179: 57

Sheet Matchup
A1: Vegas Lines | B1: Spread | C1: Total | D1: MyPRSPREAD | E1: YPPPR | H1: Model Predictions | K1: Cover_Pred_% | L1: Over_Pred_% | M1: Kneighbors Total | P1: 2024 Total/ATS | Q1: Over | R1: Under | S1: Cover | T1: Not Cover
A2: =P5 -> #VALUE! | B2: {=_xlfn.XLOOKUP($O$5, _xlfn._xlws.FILTER('Model Predictions'!$D$2:$D$179, 'Model Predictions'!$A$2:$A$179=12), _xlfn._xlws.FILTER('Model Predictions'!$E$2:$E$179, 'Model Predictions'!$A$2:$A$179=12), " ")} | C2: {=_xlfn.XLOOKUP($O$5, _xlfn._xlws.FILTER('Model Predictions'!$D$2:$D$179, 'Model Predictions'!$A$2:$A$179=12), _xlfn._xlws.FILTER('Model Predictions'!$F$2:$F$179, 'Model Predictions'!$A$2:$A$179=12), " ")} | D2: =_xlfn.XLOOKUP(P3,'Self PR'!B:B,'Self PR'!D:D," ")-_xlfn.XLOOKUP(P5,'Self PR'!B:B,'Self PR'!D:D," ") -2 -> -14.6 | E2: 2025 | F2: =_xlfn.XLOOKUP($C$10,'Power Rating'!$A:$A,'Power Rating'!$D:$D," ")-_xlfn.XLOOKUP($G$10,'Power Rating'!$A:$A,'Power Rating'!$D:$D," ") -2 -> #REF! | H2: =P3 -> #VALUE! | I2: {=_xlfn.XLOOKUP($O$3, _xlfn._xlws.FILTER('Model Predictions'!$C$2:$C$179, 'Model Predictions'!$A$2:$A$179=12), _xlfn._xlws.FILTER('Model Predictions'!$K$2:$K$179, 'Model Predictions'!$A$2:$A$179=12), " ")} | K2: {=_xlfn.XLOOKUP($O$5, _xlfn._xlws.FILTER('Model Predictions'!$D$2:$D$179, 'Model Predictions'!$A$2:$A$179=12), _xlfn._xlws.FILTER('Model Predictions'!$P$2:$P$179, 'Model Predictions'!$A$2:$A$179=12), " ") %} -> #VALUE! | L2: {=_xlfn.XLOOKUP($O$5, _xlfn._xlws.FILTER('Model Predictions'!$D$2:$D$179, 'Model Predictions'!$A$2:$A$179=12), _xlfn._xlws.FILTER('Model Predictions'!$N$2:$N$179, 'Model Predictions'!$A$2:$A$179=12), " ")%} -> #VALUE! | M2: {=_xlfn.XLOOKUP($O$5, _xlfn._xlws.FILTER('Model Predictions'!$D$2:$D$179, 'Model Predictions'!$A$2:$A$179=12), _xlfn._xlws.FILTER('Model Predictions'!$G$2:$G$179, 'Model Predictions'!$A$2:$A$179=12), " ")}
E3: Last 3 | F3: =_xlfn.XLOOKUP($C$10,'Power Rating'!$F:$F,'Power Rating'!$I:$I," ")-_xlfn.XLOOKUP($G$10,'Power Rating'!$F:$F,'Power Rating'!$I:$I," ") -2 -> #VALUE! | O3: =_xlfn.XLOOKUP(P3,Teams!D:D,Teams!E:E, " ") -> CIN | P3: =A10 -> #VALUE! | Q3: =_xlfn.XLOOKUP(O3,'2024 Over_Under'!K:K,'2024 Over_Under'!M:M, " ") -> 5 | R3: =_xlfn.XLOOKUP(O3,'2024 Over_Under'!K:K,'2024 Over_Under'!N:N, " ") -> 4 | S3: =_xlfn.XLOOKUP(O3,'2024 Over_Under'!K:K,'2024 Over_Under'!O:O, " ") -> 7 | T3: =_xlfn.XLOOKUP(O3,'2024 Over_Under'!K:K,'2024 Over_Under'!P:P, " ") -> 2
E4: Home | F4: =_xlfn.XLOOKUP($C$10,'Power Rating'!$P:$P,'Power Rating'!$S:$S," ")-_xlfn.XLOOKUP($G$10,'Power Rating'!$K:$K,'Power Rating'!$N:$N," ") -2 -> #VALUE! | H4: =P5 -> #VALUE! | I4: {=_xlfn.XLOOKUP($O$5, _xlfn._xlws.FILTER('Model Predictions'!$D$2:$D$179, 'Model Predictions'!$A$2:$A$179=12), _xlfn._xlws.FILTER('Model Predictions'!$L$2:$L$179, 'Model Predictions'!$A$2:$A$179=12), " ")} | K4: Model_Cover_Pred | M4: Total Kneighbors
K5: ='Model Predictions'!AP2 -> 0.47560976 | M5: ='Model Predictions'!AO2 -> 0.56097561 | O5: =_xlfn.XLOOKUP(P5,Teams!D:D,Teams!E:E, " ") -> BUF | P5: =I10 -> #VALUE! | Q5: =_xlfn.XLOOKUP($O$5,'2024 Over_Under'!$R:$R,'2024 Over_Under'!T:T, " ") -> 7 | R5: =_xlfn.XLOOKUP($O$5,'2024 Over_Under'!$R:$R,'2024 Over_Under'!U:U, " ") -> 1 | S5: =_xlfn.XLOOKUP($O$5,'2024 Over_Under'!$R:$R,'2024 Over_Under'!V:V, " ") -> 5 | T5: =_xlfn.XLOOKUP($O$5,'2024 Over_Under'!$R:$R,'2024 Over_Under'!W:W, " ") -> 3
K7: =(C12+H12)/2 -> 22.85 | L7: =(U12+P12)/2 -> 31.3
L8: =K7+L7 -> 54.15
C9: Away Team Offense | G9: Home Team Defense | P9: Away Team Defense | T9: Home Team Offense
A10: =_xlfn.XLOOKUP(C10,Teams!$B:$B,Teams!$D:$D, " ") -> #VALUE! | C10: Cincinnati Bengals | G10: Buffalo Bills | I10: =_xlfn.XLOOKUP(G10,Teams!$B:$B,Teams!$D:$D, " ") -> #VALUE! | N10: =_xlfn.XLOOKUP(P10,Teams!$B:$B,Teams!$D:$D, " ") -> #VALUE! | P10: =C10 -> Cincinnati Bengals | T10: =G10 -> Buffalo Bills | V10: =_xlfn.XLOOKUP(T10,Teams!$B:$B,Teams!$D:$D, " ") -> #VALUE!
C12: =_xlfn.XLOOKUP($C$10,'Offense Data 2025'!$B$120:$B$151,'Offense Data 2025'!$U$120:$U$151, " ") -> 22.8 | D12: =_xlfn.RANK.EQ(C12,'Offense Data 2025'!$U$120:$U$151,0) -> #N/A | E12: Points Per Game | G12: =_xlfn.RANK.EQ(H12,'Defense Data 2025'!$U$120:$U$151,1) -> 14 | H12: =_xlfn.XLOOKUP($G$10,'Defense Data 2025'!$B$120:$B$151,'Defense Data 2025'!$U$120:$U$151, " ") -> 22.9 | P12: =_xlfn.XLOOKUP($C$10,'Defense Data 2025'!$B$120:$B$151,'Defense Data 2025'!$U$120:$U$151, " ") -> 33.4 | Q12: =_xlfn.RANK.EQ(P12,'Defense Data 2025'!$U$120:$U$151,1) -> 32 | R12: Points Per Game | T12: =_xlfn.RANK.EQ(U12,'Offense Data 2025'!$U$120:$U$151,0) -> #N/A | U12: =_xlfn.XLOOKUP($G$10,'Offense Data 2025'!$B$120:$B$151,'Offense Data 2025'!$U$120:$U$151, " ") -> 29.2
C13: Passing Stats | P13: Passing Stats
C14: =_xlfn.XLOOKUP($C$10,'Offense Data 2025'!$B$42:$B$73,'Offense Data 2025'!$F$42:$F$73, " ") -> 63.3 | D14: =_xlfn.RANK.EQ(C14,'Offense Data 2025'!$F$42:$F$73,0) -> 22 | E14: Passing % | G14: =_xlfn.RANK.EQ(H14,'Defense Data 2025'!$F$42:$F$73,1) -> 5 | H14: =_xlfn.XLOOKUP($G$10,'Defense Data 2025'!$B$42:$B$73,'Defense Data 2025'!$F$42:$F$73, " ") -> 61.8 | P14: =_xlfn.XLOOKUP($C$10,'Defense Data 2025'!$B$42:$B$73,'Defense Data 2025'!$F$42:$F$73, " ") -> 67.2 | Q14: =_xlfn.RANK.EQ(P14,'Defense Data 2025'!$F$42:$F$73,1) -> 22 | R14: Passing % | T14: =_xlfn.RANK.EQ(U14,'Offense Data 2025'!$F$42:$F$73,0) -> 5 | U14: =_xlfn.XLOOKUP($G$10,'Offense Data 2025'!$B$42:$B$73,'Offense Data 2025'!$F$42:$F$73, " ") -> 69.2
C15: =_xlfn.XLOOKUP($C$10,'Offense Data 2025'!$B$42:$B$73,'Offense Data 2025'!$P$42:$P$73, " ") -> 225.7 | D15: =_xlfn.RANK.EQ(C15,'Offense Data 2025'!$P$42:$P$73,0) -> 14 | E15: Passing Yards/Game | G15: =_xlfn.RANK.EQ(H15,'Defense Data 2025'!$P$42:$P$73,1) -> 2 | H15: =_xlfn.XLOOKUP($G$10,'Defense Data 2025'!$B$42:$B$73,'Defense Data 2025'!$P$42:$P$73, " ") -> 169.7 | P15: =_xlfn.XLOOKUP($C$10,'Defense Data 2025'!$B$42:$B$73,'Defense Data 2025'!$P$42:$P$73, " ") -> 257.3 | Q15: =_xlfn.RANK.EQ(P15,'Defense Data 2025'!$P$42:$P$73,1) -> 31 | R15: Passing Yards/Game | T15: =_xlfn.RANK.EQ(U15,'Offense Data 2025'!$P$42:$P$73,0) -> 8 | U15: =_xlfn.XLOOKUP($G$10,'Offense Data 2025'!$B$42:$B$73,'Offense Data 2025'!$P$42:$P$73, " ") -> 239.8
C16: =_xlfn.XLOOKUP($C$10,'Offense Data 2025'!$B$42:$B$73,'Offense Data 2025'!$G$42:$G$73, " ") -> 2257 | D16: =_xlfn.RANK.EQ(C16,'Offense Data 2025'!$G$42:$G$73,0) -> 16 | E16: Passing Yards | G16: =_xlfn.RANK.EQ(H16,'Defense Data 2025'!$G$42:$G$73,1) -> 2 | H16: =_xlfn.XLOOKUP($G$10,'Defense Data 2025'!$B$42:$B$73,'Defense Data 2025'!$G$42:$G$73, " ") -> 1697 | P16: =_xlfn.XLOOKUP($C$10,'Defense Data 2025'!$B$42:$B$73,'Defense Data 2025'!$G$42:$G$73, " ") -> 2573 | Q16: =_xlfn.RANK.EQ(P16,'Defense Data 2025'!$G$42:$G$73,1) -> 29 | R16: Passing Yards | T16: =_xlfn.RANK.EQ(U16,'Offense Data 2025'!$G$42:$G$73,0) -> 9 | U16: =_xlfn.XLOOKUP($G$10,'Offense Data 2025'!$B$42:$B$73,'Offense Data 2025'!$G$42:$G$73, " ") -> 2398
C17: =_xlfn.XLOOKUP($C$10,'Offense Data 2025'!$B$42:$B$73,'Offense Data 2025'!$H$42:$H$73, " ") -> 20 | D17: =_xlfn.RANK.EQ(C17,'Offense Data 2025'!$H$42:$H$73,0) -> 4 | E17: Passing TDs | G17: =_xlfn.RANK.EQ(H17,'Defense Data 2025'!$H$42:$H$73,1) -> 4 | H17: =_xlfn.XLOOKUP($G$10,'Defense Data 2025'!$B$42:$B$73,'Defense Data 2025'!$H$42:$H$73, " ") -> 10 | P17: =_xlfn.XLOOKUP($C$10,'Defense Data 2025'!$B$42:$B$73,'Defense Data 2025'!$H$42:$H$73, " ") -> 25 | Q17: =_xlfn.RANK.EQ(P17,'Defense Data 2025'!$H$42:$H$73,1) -> 32 | R17: Passing TDs | T17: =_xlfn.RANK.EQ(U17,'Offense Data 2025'!$H$42:$H$73,0) -> 9 | U17: =_xlfn.XLOOKUP($G$10,'Offense Data 2025'!$B$42:$B$73,'Offense Data 2025'!$H$42:$H$73, " ") -> 18
C18: =_xlfn.XLOOKUP($C$10,'Offense Data 2025'!$B$42:$B$73,'Offense Data 2025'!$J$42:$J$73, " ") -> 11 | D18: =_xlfn.RANK.EQ(C18,'Offense Data 2025'!$J$42:$J$73,1) -> 28 | E18: Interceptions Thrown | G18: =_xlfn.RANK.EQ(H18,'Defense Data 2025'!$J$42:$J$73,0) -> 14 | H18: =_xlfn.XLOOKUP($G$10,'Defense Data 2025'!$B$42:$B$73,'Defense Data 2025'!$J$42:$J$73, " ") -> 7 | P18: =_xlfn.XLOOKUP($C$10,'Defense Data 2025'!$B$42:$B$73,'Defense Data 2025'!$J$42:$J$73, " ") -> 8 | Q18: =_xlfn.RANK.EQ(P18,'Defense Data 2025'!$J$42:$J$73,0) -> 11 | R18: Interceptions | T18: =_xlfn.RANK.EQ(U18,'Offense Data 2025'!$J$42:$J$73,1) -> 14 | U18: =_xlfn.XLOOKUP($G$10,'Offense Data 2025'!$B$42:$B$73,'Offense Data 2025'!$J$42:$J$73, " ") -> 7
C19: =_xlfn.XLOOKUP($C$10,'Offense Data 2025'!$B$42:$B$73,'Offense Data 2025'!$R$42:$R$73, " ") -> 23 | D19: =_xlfn.RANK.EQ(C19,'Offense Data 2025'!$R$42:$R$73,1) -> 15 | E19: Times Sacked | G19: =_xlfn.RANK.EQ(H19,'Defense Data 2025'!$R$42:$R$73,0) -> 10 | H19: =_xlfn.XLOOKUP($G$10,'Defense Data 2025'!$B$42:$B$73,'Defense Data 2025'!$R$42:$R$73, " ") -> 26 | P19: =_xlfn.XLOOKUP($C$10,'Defense Data 2025'!$B$42:$B$73,'Defense Data 2025'!$R$42:$R$73, " ") -> 14 | Q19: =_xlfn.RANK.EQ(P19,'Defense Data 2025'!$R$42:$R$73,0) -> 31 | R19: Times Sacked | T19: =_xlfn.RANK.EQ(U19,'Offense Data 2025'!$R$42:$R$73,1) -> 10 | U19: =_xlfn.XLOOKUP($G$10,'Offense Data 2025'!$B$42:$B$73,'Offense Data 2025'!$R$42:$R$73, " ") -> 20
C20: Rushing Stats | P20: Rushing Stats
C21: =_xlfn.XLOOKUP($C$10,'Offense Data 2025'!$B$81:$B$112,'Offense Data 2025'!$D$81:$D$112, " ") -> 191 | D21: =_xlfn.RANK.EQ(C21,'Offense Data 2025'!$D$81:$D$112,0) -> 32 | E21: Rushing Attempts | G21: =_xlfn.RANK.EQ(H21,'Defense Data 2025'!$D$81:$D$112,1) -> 2 | H21: =_xlfn.XLOOKUP($G$10,'Defense Data 2025'!$B$42:$B$73,'Defense Data 2025'!$D$81:$D$112, " ") -> 226 | P21: =_xlfn.XLOOKUP($C$10,'Defense Data 2025'!$B$42:$B$73,'Defense Data 2025'!$D$81:$D$112, " ") -> 282 | Q21: =_xlfn.RANK.EQ(P21,'Defense Data 2025'!$D$81:$D$112,1) -> 21 | R21: Rushing Attempts | T21: =_xlfn.RANK.EQ(U21,'Offense Data 2025'!$D$81:$D$112,0) -> 7 | U21: =_xlfn.XLOOKUP($G$10,'Offense Data 2025'!$B$81:$B$112,'Offense Data 2025'!$D$81:$D$112, " ") -> 301
C22: =_xlfn.XLOOKUP($C$10,'Offense Data 2025'!$B$81:$B$112,'Offense Data 2025'!$E$81:$E$112, " ") -> 814 | D22: =_xlfn.RANK.EQ(C22,'Offense Data 2025'!$E$81:$E$112,0) -> 30 | E22: Rushing Yards | G22: =_xlfn.RANK.EQ(H22,'Defense Data 2025'!$E$81:$E$112,1) -> 2 | H22: =_xlfn.XLOOKUP($G$10,'Defense Data 2025'!$B$42:$B$73,'Defense Data 2025'!$E$81:$E$112, " ") -> 871 | P22: =_xlfn.XLOOKUP($C$10,'Defense Data 2025'!$B$42:$B$73,'Defense Data 2025'!$E$81:$E$112, " ") -> 1530 | Q22: =_xlfn.RANK.EQ(P22,'Defense Data 2025'!$E$81:$E$112,1) -> 29 | R22: Rushing Yards | T22: =_xlfn.RANK.EQ(U22,'Offense Data 2025'!$E$81:$E$112,0) -> 2 | U22: =_xlfn.XLOOKUP($G$10,'Offense Data 2025'!$B$81:$B$112,'Offense Data 2025'!$E$81:$E$112, " ") -> 1476
C23: =_xlfn.XLOOKUP($C$10,'Offense Data 2025'!$B$81:$B$112,'Offense Data 2025'!$H$81:$H$112, " ") -> 4.3 | D23: =_xlfn.RANK.EQ(C23,'Offense Data 2025'!$H$81:$H$112,0) -> 17 | E23: Rushing Yards per attempt | G23: =_xlfn.RANK.EQ(H23,'Defense Data 2025'!$G$81:$G$112,1) -> 4 | H23: =_xlfn.XLOOKUP($G$10,'Defense Data 2025'!$B$42:$B$73,'Defense Data 2025'!$G$81:$G$112, " ") -> 3.9 | P23: =_xlfn.XLOOKUP($C$10,'Defense Data 2025'!$B$42:$B$73,'Defense Data 2025'!$G$81:$G$112, " ") -> 5.4 | Q23: =_xlfn.RANK.EQ(P23,'Defense Data 2025'!$G$81:$G$112,1) -> 31 | R23: Rushing Yards per attempt | T23: =_xlfn.RANK.EQ(U23,'Offense Data 2025'!$H$81:$H$112,0) -> 4 | U23: =_xlfn.XLOOKUP($G$10,'Offense Data 2025'!$B$81:$B$112,'Offense Data 2025'!$H$81:$H$112, " ") -> 4.9
C24: =_xlfn.XLOOKUP($C$10,'Offense Data 2025'!$B$81:$B$112,'Offense Data 2025'!$I$81:$I$112, " ") -> 81.4 | D24: =_xlfn.RANK.EQ(C24,'Offense Data 2025'!$I$81:$I$112,0) -> 30 | E24: Rushing Yards Per Game | G24: =_xlfn.RANK.EQ(H24,'Defense Data 2025'!$H$81:$H$112,1) -> 3 | H24: =_xlfn.XLOOKUP($G$10,'Defense Data 2025'!$B$42:$B$73,'Defense Data 2025'!$H$81:$H$112, " ") -> 87.1 | P24: =_xlfn.XLOOKUP($C$10,'Defense Data 2025'!$B$42:$B$73,'Defense Data 2025'!$H$81:$H$112, " ") -> 153 | Q24: =_xlfn.RANK.EQ(P24,'Defense Data 2025'!$H$81:$H$112,1) -> 31 | R24: Rushing Yards Per Game | T24: =_xlfn.RANK.EQ(U24,'Offense Data 2025'!$I$81:$I$112,0) -> 1 | U24: =_xlfn.XLOOKUP($G$10,'Offense Data 2025'!$B$81:$B$112,'Offense Data 2025'!$I$81:$I$112, " ") -> 147.6
C25: =_xlfn.XLOOKUP($C$10,'Offense Data 2025'!$B$81:$B$112,'Offense Data 2025'!$F$81:$F$112, " ") -> 5 | D25: =_xlfn.RANK.EQ(C25,'Offense Data 2025'!$F$81:$F$112,0) -> 26 | E25: Rushing Touchdowns | G25: =_xlfn.RANK.EQ(H25,'Defense Data 2025'!$F$81:$F$112,1) -> 7 | H25: =_xlfn.XLOOKUP($G$10,'Defense Data 2025'!$B$42:$B$73,'Defense Data 2025'!$F$81:$F$112, " ") -> 8 | P25: =_xlfn.XLOOKUP($C$10,'Defense Data 2025'!$B$42:$B$73,'Defense Data 2025'!$F$81:$F$112, " ") -> 17 | Q25: =_xlfn.RANK.EQ(P25,'Defense Data 2025'!$F$81:$F$112,1) -> 32 | R25: Rushing Touchdowns | T25: =_xlfn.RANK.EQ(U25,'Offense Data 2025'!$F$81:$F$112,0) -> 2 | U25: =_xlfn.XLOOKUP($G$10,'Offense Data 2025'!$B$81:$B$112,'Offense Data 2025'!$F$81:$F$112, " ") -> 19
C26: =_xlfn.XLOOKUP($C$10,'Offense Data 2025'!$B$81:$B$112,'Offense Data 2025'!$J$81:$J$112, " ") -> 9 | D26: =_xlfn.RANK.EQ(C26,'Offense Data 2025'!$J$81:$J$112,1) -> 8 | E26: Rushing Fumbles | G26: =_xlfn.RANK.EQ(H26,'Defense Data 2025'!$I$3:$I$34,0) -> 8 | H26: =_xlfn.XLOOKUP(G10,'Defense Data 2025'!$B$3:$B$34,'Defense Data 2025'!$I$3:$I$34, " ") -> 6 | P26: =_xlfn.XLOOKUP(C10,'Defense Data 2025'!$B$3:$B$34,'Defense Data 2025'!$I$3:$I$34, " ") -> 1 | Q26: =_xlfn.RANK.EQ(P26,'Defense Data 2025'!$I$3:$I$34,0) -> 30 | R26: Rushing Fumbles | T26: =_xlfn.RANK.EQ(U26,'Offense Data 2025'!$J$81:$J$112,1) -> 21 | U26: =_xlfn.XLOOKUP($G$10,'Offense Data 2025'!$B$81:$B$112,'Offense Data 2025'!$J$81:$J$112, " ") -> 12
C27: Drive Averages
C28: =_xlfn.XLOOKUP($C$10,'Offense Data 2025'!$B$159:$B$190,'Offense Data 2025'!$F$159:$F$190, " ") -> 37.4 | D28: =_xlfn.RANK.EQ(C28,'Offense Data 2025'!$F$159:$F$190,0) -> 21 | E28: % end w/points | G28: =_xlfn.RANK.EQ(H28,'Offense Data 2025'!$F$159:$F$190,0) -> 4 | H28: =_xlfn.XLOOKUP(G10,'Offense Data 2025'!$B$159:$B$190,'Offense Data 2025'!$F$159:$F$190, " ") -> 47.2
C29: =_xlfn.XLOOKUP($C$10,'Offense Data 2025'!$B$159:$B$190,'Offense Data 2025'!$H$159:$H$190, " ") -> 5.7 | D29: =_xlfn.RANK.EQ(C29,'Offense Data 2025'!$H$159:$H$190,0) -> 22 | E29: average play per drive | G29: =_xlfn.RANK.EQ(H29,'Offense Data 2025'!$H$159:$H$190,0) -> 16 | H29: =_xlfn.XLOOKUP(G10,'Offense Data 2025'!$B$159:$B$190,'Offense Data 2025'!$H$159:$H$190, " ") -> 6
C30: =_xlfn.XLOOKUP($C$10,'Offense Data 2025'!$B$159:$B$190,'Offense Data 2025'!$I$159:$I$190, " ") -> 28.7 | D30: =_xlfn.RANK.EQ(C30,'Offense Data 2025'!$I$159:$I$190,0) -> 25 | E30: Net yards per drive | G30: =_xlfn.RANK.EQ(H30,'Offense Data 2025'!$I$159:$I$190,0) -> 3 | H30: =_xlfn.XLOOKUP(G10,'Offense Data 2025'!$B$159:$B$190,'Offense Data 2025'!$I$159:$I$190, " ") -> 36.5
C31: =_xlfn.XLOOKUP($C$10,'Offense Data 2025'!$B$159:$B$190,'Offense Data 2025'!$K$159:$K$190, " ") -> 0.10555556 | D31: =_xlfn.RANK.EQ(C31,'Offense Data 2025'!$K$159:$K$190,0) -> 31 | E31: Drive Duration | G31: =_xlfn.RANK.EQ(H31,'Offense Data 2025'!$K$159:$K$190,0) -> 8 | H31: =_xlfn.XLOOKUP(G10,'Offense Data 2025'!$B$159:$B$190,'Offense Data 2025'!$K$159:$K$190, " ") -> 0.12708333

Sheet Power Rating
B1: 2025 | C1: Power Rating | D1: Power Rating | F1: Last 3 | H1: Power Rating | I1: Power Rating | K1: Home | M1: Power Rating | N1: Power Rating | P1: Away | R1: Power Rating | S1: Power Rating
A2: =_xlfn.XLOOKUP(B2,Teams!A:A,Teams!B:B, " ") -> Buffalo Bills | B2: Buffalo | C2: {=_xlfn.XLOOKUP(A2,YPP!$A$2:$A$33,#REF!, " ") - _xlfn.XLOOKUP(A2,YPP!$R$2:$R$33,#REF!, " ")} -> #REF! | D2: =C2*-1 -> #REF! | F2: =_xlfn.XLOOKUP(G2,Teams!$A:$A,Teams!$B:$B, " ") -> Buffalo Bills | G2: Buffalo | H2: =_xlfn.XLOOKUP(F2,YPP!$A:$A,YPP!$N:$N, " ")-_xlfn.XLOOKUP(F2,YPP!$T:$T,YPP!$X:$X, " ") -> #VALUE! | I2: =H2*-1 -> #VALUE! | K2: =_xlfn.XLOOKUP(L2,Teams!$A:$A,Teams!$B:$B, " ") -> Buffalo Bills | L2: Buffalo | M2: =_xlfn.XLOOKUP(K2,YPP!$A:$A,YPP!$P:$P, " ")-_xlfn.XLOOKUP(K2,YPP!$T:$T,YPP!$Z:$Z, " ") -> #VALUE! | N2: =M2*-1 -> #VALUE! | P2: =_xlfn.XLOOKUP(Q2,Teams!$A:$A,Teams!$B:$B, " ") -> Buffalo Bills | Q2: Buffalo | R2: =_xlfn.XLOOKUP(P2,YPP!$A:$A,YPP!$Q:$Q, " ")-_xlfn.XLOOKUP(P2,YPP!$T:$T,YPP!$AA:$AA, " ") -> #VALUE! | S2: =R2*-1 -> #VALUE!
A3: =_xlfn.XLOOKUP(B3,Teams!A:A,Teams!B:B, " ") -> Los Angeles Chargers | B3: LA Chargers | C3: {=_xlfn.XLOOKUP(A3,YPP!$A$2:$A$33,#REF!, " ") - _xlfn.XLOOKUP(A3,YPP!$R$2:$R$33,#REF!, " ")} -> #REF! | D3: =C3*-1 -> #REF! | F3: =_xlfn.XLOOKUP(G3,Teams!A:A,Teams!B:B, " ") -> Detroit Lions | G3: Detroit | H3: =_xlfn.XLOOKUP(F3,YPP!$A:$A,YPP!$N:$N, " ")-_xlfn.XLOOKUP(F3,YPP!$T:$T,YPP!$X:$X, " ") -> #VALUE! | I3: =H3*-1 -> #VALUE! | K3: =_xlfn.XLOOKUP(L3,Teams!$A:$A,Teams!$B:$B, " ") -> Detroit Lions | L3: Detroit | M3: =_xlfn.XLOOKUP(K3,YPP!$A:$A,YPP!$P:$P, " ")-_xlfn.XLOOKUP(K3,YPP!$T:$T,YPP!$Z:$Z, " ") -> #VALUE! | N3: =M3*-1 -> #VALUE! | P3: =_xlfn.XLOOKUP(Q3,Teams!$A:$A,Teams!$B:$B, " ") -> Detroit Lions | Q3: Detroit | R3: =_xlfn.XLOOKUP(P3,YPP!$A:$A,YPP!$Q:$Q, " ")-_xlfn.XLOOKUP(P3,YPP!$T:$T,YPP!$AA:$AA, " ") -> #VALUE! | S3: =R3*-1 -> #VALUE!
A4: =_xlfn.XLOOKUP(B4,Teams!A:A,Teams!B:B, " ") -> Denver Broncos | B4: Denver | C4: {=_xlfn.XLOOKUP(A4,YPP!$A$2:$A$33,#REF!, " ") - _xlfn.XLOOKUP(A4,YPP!$R$2:$R$33,#REF!, " ")} -> #REF! | D4: =C4*-1 -> #REF! | F4: =_xlfn.XLOOKUP(G4,Teams!A:A,Teams!B:B, " ") -> Philadelphia Eagles | G4: Philadelphia | H4: =_xlfn.XLOOKUP(F4,YPP!$A:$A,YPP!$N:$N, " ")-_xlfn.XLOOKUP(F4,YPP!$T:$T,YPP!$X:$X, " ") -> #VALUE! | I4: =H4*-1 -> #VALUE! | K4: =_xlfn.XLOOKUP(L4,Teams!$A:$A,Teams!$B:$B, " ") -> Philadelphia Eagles | L4: Philadelphia | M4: =_xlfn.XLOOKUP(K4,YPP!$A:$A,YPP!$P:$P, " ")-_xlfn.XLOOKUP(K4,YPP!$T:$T,YPP!$Z:$Z, " ") -> #VALUE! | N4: =M4*-1 -> #VALUE! | P4: =_xlfn.XLOOKUP(Q4,Teams!$A:$A,Teams!$B:$B, " ") -> Philadelphia Eagles | Q4: Philadelphia | R4: =_xlfn.XLOOKUP(P4,YPP!$A:$A,YPP!$Q:$Q, " ")-_xlfn.XLOOKUP(P4,YPP!$T:$T,YPP!$AA:$AA, " ") -> #VALUE! | S4: =R4*-1 -> #VALUE!
A5: =_xlfn.XLOOKUP(B5,Teams!A:A,Teams!B:B, " ") -> Detroit Lions | B5: Detroit | C5: {=_xlfn.XLOOKUP(A5,YPP!$A$2:$A$33,#REF!, " ") - _xlfn.XLOOKUP(A5,YPP!$R$2:$R$33,#REF!, " ")} -> #REF! | D5: =C5*-1 -> #REF! | F5: =_xlfn.XLOOKUP(G5,Teams!A:A,Teams!B:B, " ") -> Washington Commanders | G5: Washington | H5: =_xlfn.XLOOKUP(F5,YPP!$A:$A,YPP!$N:$N, " ")-_xlfn.XLOOKUP(F5,YPP!$T:$T,YPP!$X:$X, " ") -> #VALUE! | I5: =H5*-1 -> #VALUE! | K5: =_xlfn.XLOOKUP(L5,Teams!$A:$A,Teams!$B:$B, " ") -> Washington Commanders | L5: Washington | M5: =_xlfn.XLOOKUP(K5,YPP!$A:$A,YPP!$P:$P, " ")-_xlfn.XLOOKUP(K5,YPP!$T:$T,YPP!$Z:$Z, " ") -> #VALUE! | N5: =M5*-1 -> #VALUE! | P5: =_xlfn.XLOOKUP(Q5,Teams!$A:$A,Teams!$B:$B, " ") -> Washington Commanders | Q5: Washington | R5: =_xlfn.XLOOKUP(P5,YPP!$A:$A,YPP!$Q:$Q, " ")-_xlfn.XLOOKUP(P5,YPP!$T:$T,YPP!$AA:$AA, " ") -> #VALUE! | S5: =R5*-1 -> #VALUE!
A6: =_xlfn.XLOOKUP(B6,Teams!A:A,Teams!B:B, " ") -> Philadelphia Eagles | B6: Philadelphia | C6: {=_xlfn.XLOOKUP(A6,YPP!$A$2:$A$33,#REF!, " ") - _xlfn.XLOOKUP(A6,YPP!$R$2:$R$33,#REF!, " ")} -> #REF! | D6: =C6*-1 -> #REF! | F6: =_xlfn.XLOOKUP(G6,Teams!A:A,Teams!B:B, " ") -> Cincinnati Bengals | G6: Cincinnati | H6: =_xlfn.XLOOKUP(F6,YPP!$A:$A,YPP!$N:$N, " ")-_xlfn.XLOOKUP(F6,YPP!$T:$T,YPP!$X:$X, " ") -> #VALUE! | I6: =H6*-1 -> #VALUE! | K6: =_xlfn.XLOOKUP(L6,Teams!$A:$A,Teams!$B:$B, " ") -> Cincinnati Bengals | L6: Cincinnati | M6: =_xlfn.XLOOKUP(K6,YPP!$A:$A,YPP!$P:$P, " ")-_xlfn.XLOOKUP(K6,YPP!$T:$T,YPP!$Z:$Z, " ") -> #VALUE! | N6: =M6*-1 -> #VALUE! | P6: =_xlfn.XLOOKUP(Q6,Teams!$A:$A,Teams!$B:$B, " ") -> Cincinnati Bengals | Q6: Cincinnati | R6: =_xlfn.XLOOKUP(P6,YPP!$A:$A,YPP!$Q:$Q, " ")-_xlfn.XLOOKUP(P6,YPP!$T:$T,YPP!$AA:$AA, " ") -> #VALUE! | S6: =R6*-1 -> #VALUE!
A7: =_xlfn.XLOOKUP(B7,Teams!A:A,Teams!B:B, " ") -> Minnesota Vikings | B7: Minnesota | C7: {=_xlfn.XLOOKUP(A7,YPP!$A$2:$A$33,#REF!, " ") - _xlfn.XLOOKUP(A7,YPP!$R$2:$R$33,#REF!, " ")} -> #REF! | D7: =C7*-1 -> #REF! | F7: =_xlfn.XLOOKUP(G7,Teams!A:A,Teams!B:B, " ") -> Denver Broncos | G7: Denver | H7: =_xlfn.XLOOKUP(F7,YPP!$A:$A,YPP!$N:$N, " ")-_xlfn.XLOOKUP(F7,YPP!$T:$T,YPP!$X:$X, " ") -> #VALUE! | I7: =H7*-1 -> #VALUE! | K7: =_xlfn.XLOOKUP(L7,Teams!$A:$A,Teams!$B:$B, " ") -> Denver Broncos | L7: Denver | M7: =_xlfn.XLOOKUP(K7,YPP!$A:$A,YPP!$P:$P, " ")-_xlfn.XLOOKUP(K7,YPP!$T:$T,YPP!$Z:$Z, " ") -> #VALUE! | N7: =M7*-1 -> #VALUE! | P7: =_xlfn.XLOOKUP(Q7,Teams!$A:$A,Teams!$B:$B, " ") -> Denver Broncos | Q7: Denver | R7: =_xlfn.XLOOKUP(P7,YPP!$A:$A,YPP!$Q:$Q, " ")-_xlfn.XLOOKUP(P7,YPP!$T:$T,YPP!$AA:$AA, " ") -> #VALUE! | S7: =R7*-1 -> #VALUE!
A8: =_xlfn.XLOOKUP(B8,Teams!A:A,Teams!B:B, " ") -> Kansas City Chiefs | B8: Kansas City | C8: {=_xlfn.XLOOKUP(A8,YPP!$A$2:$A$33,#REF!, " ") - _xlfn.XLOOKUP(A8,YPP!$R$2:$R$33,#REF!, " ")} -> #REF! | D8: =C8*-1 -> #REF! | F8: =_xlfn.XLOOKUP(G8,Teams!A:A,Teams!B:B, " ") -> Tampa Bay Buccaneers | G8: Tampa Bay | H8: =_xlfn.XLOOKUP(F8,YPP!$A:$A,YPP!$N:$N, " ")-_xlfn.XLOOKUP(F8,YPP!$T:$T,YPP!$X:$X, " ") -> #VALUE! | I8: =H8*-1 -> #VALUE! | K8: =_xlfn.XLOOKUP(L8,Teams!$A:$A,Teams!$B:$B, " ") -> Tampa Bay Buccaneers | L8: Tampa Bay | M8: =_xlfn.XLOOKUP(K8,YPP!$A:$A,YPP!$P:$P, " ")-_xlfn.XLOOKUP(K8,YPP!$T:$T,YPP!$Z:$Z, " ") -> #VALUE! | N8: =M8*-1 -> #VALUE! | P8: =_xlfn.XLOOKUP(Q8,Teams!$A:$A,Teams!$B:$B, " ") -> Tampa Bay Buccaneers | Q8: Tampa Bay | R8: =_xlfn.XLOOKUP(P8,YPP!$A:$A,YPP!$Q:$Q, " ")-_xlfn.XLOOKUP(P8,YPP!$T:$T,YPP!$AA:$AA, " ") -> #VALUE! | S8: =R8*-1 -> #VALUE!
A9: =_xlfn.XLOOKUP(B9,Teams!A:A,Teams!B:B, " ") -> Green Bay Packers | B9: Green Bay | C9: {=_xlfn.XLOOKUP(A9,YPP!$A$2:$A$33,#REF!, " ") - _xlfn.XLOOKUP(A9,YPP!$R$2:$R$33,#REF!, " ")} -> #REF! | D9: =C9*-1 -> #REF! | F9: =_xlfn.XLOOKUP(G9,Teams!A:A,Teams!B:B, " ") -> Kansas City Chiefs | G9: Kansas City | H9: =_xlfn.XLOOKUP(F9,YPP!$A:$A,YPP!$N:$N, " ")-_xlfn.XLOOKUP(F9,YPP!$T:$T,YPP!$X:$X, " ") -> #VALUE! | I9: =H9*-1 -> #VALUE! | K9: =_xlfn.XLOOKUP(L9,Teams!$A:$A,Teams!$B:$B, " ") -> Kansas City Chiefs | L9: Kansas City | M9: =_xlfn.XLOOKUP(K9,YPP!$A:$A,YPP!$P:$P, " ")-_xlfn.XLOOKUP(K9,YPP!$T:$T,YPP!$Z:$Z, " ") -> #VALUE! | N9: =M9*-1 -> #VALUE! | P9: =_xlfn.XLOOKUP(Q9,Teams!$A:$A,Teams!$B:$B, " ") -> Kansas City Chiefs | Q9: Kansas City | R9: =_xlfn.XLOOKUP(P9,YPP!$A:$A,YPP!$Q:$Q, " ")-_xlfn.XLOOKUP(P9,YPP!$T:$T,YPP!$AA:$AA, " ") -> #VALUE! | S9: =R9*-1 -> #VALUE!
A10: =_xlfn.XLOOKUP(B10,Teams!A:A,Teams!B:B, " ") -> Tampa Bay Buccaneers | B10: Tampa Bay | C10: {=_xlfn.XLOOKUP(A10,YPP!$A$2:$A$33,#REF!, " ") - _xlfn.XLOOKUP(A10,YPP!$R$2:$R$33,#REF!, " ")} -> #REF! | D10: =C10*-1 -> #REF! | F10: =_xlfn.XLOOKUP(G10,Teams!A:A,Teams!B:B, " ") -> Los Angeles Chargers | G10: LA Chargers | H10: =_xlfn.XLOOKUP(F10,YPP!$A:$A,YPP!$N:$N, " ")-_xlfn.XLOOKUP(F10,YPP!$T:$T,YPP!$X:$X, " ") -> #VALUE! | I10: =H10*-1 -> #VALUE! | K10: =_xlfn.XLOOKUP(L10,Teams!$A:$A,Teams!$B:$B, " ") -> Los Angeles Chargers | L10: LA Chargers | M10: =_xlfn.XLOOKUP(K10,YPP!$A:$A,YPP!$P:$P, " ")-_xlfn.XLOOKUP(K10,YPP!$T:$T,YPP!$Z:$Z, " ") -> #VALUE! | N10: =M10*-1 -> #VALUE! | P10: =_xlfn.XLOOKUP(Q10,Teams!$A:$A,Teams!$B:$B, " ") -> Los Angeles Chargers | Q10: LA Chargers | R10: =_xlfn.XLOOKUP(P10,YPP!$A:$A,YPP!$Q:$Q, " ")-_xlfn.XLOOKUP(P10,YPP!$T:$T,YPP!$AA:$AA, " ") -> #VALUE! | S10: =R10*-1 -> #VALUE!
A11: =_xlfn.XLOOKUP(B11,Teams!A:A,Teams!B:B, " ") -> Pittsburgh Steelers | B11: Pittsburgh | C11: {=_xlfn.XLOOKUP(A11,YPP!$A$2:$A$33,#REF!, " ") - _xlfn.XLOOKUP(A11,YPP!$R$2:$R$33,#REF!, " ")} -> #REF! | D11: =C11*-1 -> #REF! | F11: =_xlfn.XLOOKUP(G11,Teams!A:A,Teams!B:B, " ") -> Minnesota Vikings | G11: Minnesota | H11: =_xlfn.XLOOKUP(F11,YPP!$A:$A,YPP!$N:$N, " ")-_xlfn.XLOOKUP(F11,YPP!$T:$T,YPP!$X:$X, " ") -> #VALUE! | I11: =H11*-1 -> #VALUE! | K11: =_xlfn.XLOOKUP(L11,Teams!$A:$A,Teams!$B:$B, " ") -> Minnesota Vikings | L11: Minnesota | M11: =_xlfn.XLOOKUP(K11,YPP!$A:$A,YPP!$P:$P, " ")-_xlfn.XLOOKUP(K11,YPP!$T:$T,YPP!$Z:$Z, " ") -> #VALUE! | N11: =M11*-1 -> #VALUE! | P11: =_xlfn.XLOOKUP(Q11,Teams!$A:$A,Teams!$B:$B, " ") -> Minnesota Vikings | Q11: Minnesota | R11: =_xlfn.XLOOKUP(P11,YPP!$A:$A,YPP!$Q:$Q, " ")-_xlfn.XLOOKUP(P11,YPP!$T:$T,YPP!$AA:$AA, " ") -> #VALUE! | S11: =R11*-1 -> #VALUE!
A12: =_xlfn.XLOOKUP(B12,Teams!A:A,Teams!B:B, " ") -> Baltimore Ravens | B12: Baltimore | C12: {=_xlfn.XLOOKUP(A12,YPP!$A$2:$A$33,#REF!, " ") - _xlfn.XLOOKUP(A12,YPP!$R$2:$R$33,#REF!, " ")} -> #REF! | D12: =C12*-1 -> #REF! | F12: =_xlfn.XLOOKUP(G12,Teams!A:A,Teams!B:B, " ") -> Green Bay Packers | G12: Green Bay | H12: =_xlfn.XLOOKUP(F12,YPP!$A:$A,YPP!$N:$N, " ")-_xlfn.XLOOKUP(F12,YPP!$T:$T,YPP!$X:$X, " ") -> #VALUE! | I12: =H12*-1 -> #VALUE! | K12: =_xlfn.XLOOKUP(L12,Teams!$A:$A,Teams!$B:$B, " ") -> Green Bay Packers | L12: Green Bay | M12: =_xlfn.XLOOKUP(K12,YPP!$A:$A,YPP!$P:$P, " ")-_xlfn.XLOOKUP(K12,YPP!$T:$T,YPP!$Z:$Z, " ") -> #VALUE! | N12: =M12*-1 -> #VALUE! | P12: =_xlfn.XLOOKUP(Q12,Teams!$A:$A,Teams!$B:$B, " ") -> Green Bay Packers | Q12: Green Bay | R12: =_xlfn.XLOOKUP(P12,YPP!$A:$A,YPP!$Q:$Q, " ")-_xlfn.XLOOKUP(P12,YPP!$T:$T,YPP!$AA:$AA, " ") -> #VALUE! | S12: =R12*-1 -> #VALUE!
A13: =_xlfn.XLOOKUP(B13,Teams!A:A,Teams!B:B, " ") -> Chicago Bears | B13: Chicago | C13: {=_xlfn.XLOOKUP(A13,YPP!$A$2:$A$33,#REF!, " ") - _xlfn.XLOOKUP(A13,YPP!$R$2:$R$33,#REF!, " ")} -> #REF! | D13: =C13*-1 -> #REF! | F13: =_xlfn.XLOOKUP(G13,Teams!A:A,Teams!B:B, " ") -> Baltimore Ravens | G13: Baltimore | H13: =_xlfn.XLOOKUP(F13,YPP!$A:$A,YPP!$N:$N, " ")-_xlfn.XLOOKUP(F13,YPP!$T:$T,YPP!$X:$X, " ") -> #VALUE! | I13: =H13*-1 -> #VALUE! | K13: =_xlfn.XLOOKUP(L13,Teams!$A:$A,Teams!$B:$B, " ") -> Baltimore Ravens | L13: Baltimore | M13: =_xlfn.XLOOKUP(K13,YPP!$A:$A,YPP!$P:$P, " ")-_xlfn.XLOOKUP(K13,YPP!$T:$T,YPP!$Z:$Z, " ") -> #VALUE! | N13: =M13*-1 -> #VALUE! | P13: =_xlfn.XLOOKUP(Q13,Teams!$A:$A,Teams!$B:$B, " ") -> Baltimore Ravens | Q13: Baltimore | R13: =_xlfn.XLOOKUP(P13,YPP!$A:$A,YPP!$Q:$Q, " ")-_xlfn.XLOOKUP(P13,YPP!$T:$T,YPP!$AA:$AA, " ") -> #VALUE! | S13: =R13*-1 -> #VALUE!
A14: =_xlfn.XLOOKUP(B14,Teams!A:A,Teams!B:B, " ") -> Washington Commanders | B14: Washington | C14: {=_xlfn.XLOOKUP(A14,YPP!$A$2:$A$33,#REF!, " ") - _xlfn.XLOOKUP(A14,YPP!$R$2:$R$33,#REF!, " ")} -> #REF! | D14: =C14*-1 -> #REF! | F14: =_xlfn.XLOOKUP(G14,Teams!A:A,Teams!B:B, " ") -> Pittsburgh Steelers | G14: Pittsburgh | H14: =_xlfn.XLOOKUP(F14,YPP!$A:$A,YPP!$N:$N, " ")-_xlfn.XLOOKUP(F14,YPP!$T:$T,YPP!$X:$X, " ") -> #VALUE! | I14: =H14*-1 -> #VALUE! | K14: =_xlfn.XLOOKUP(L14,Teams!$A:$A,Teams!$B:$B, " ") -> Pittsburgh Steelers | L14: Pittsburgh | M14: =_xlfn.XLOOKUP(K14,YPP!$A:$A,YPP!$P:$P, " ")-_xlfn.XLOOKUP(K14,YPP!$T:$T,YPP!$Z:$Z, " ") -> #VALUE! | N14: =M14*-1 -> #VALUE! | P14: =_xlfn.XLOOKUP(Q14,Teams!$A:$A,Teams!$B:$B, " ") -> Pittsburgh Steelers | Q14: Pittsburgh | R14: =_xlfn.XLOOKUP(P14,YPP!$A:$A,YPP!$Q:$Q, " ")-_xlfn.XLOOKUP(P14,YPP!$T:$T,YPP!$AA:$AA, " ") -> #VALUE! | S14: =R14*-1 -> #VALUE!
... A33: =_xlfn.XLOOKUP(B33,Teams!A:A,Teams!B:B, " ") -> Cleveland Browns | B33: Cleveland | C33: {=_xlfn.XLOOKUP(A33,YPP!$A$2:$A$33,#REF!, " ") - _xlfn.XLOOKUP(A33,YPP!$R$2:$R$33,#REF!, " ")} -> #REF! | D33: =C33*-1 -> #REF! | F33: =_xlfn.XLOOKUP(G33,Teams!A:A,Teams!B:B, " ") -> Cleveland Browns | G33: Cleveland | H33: =_xlfn.XLOOKUP(F33,YPP!$A:$A,YPP!$N:$N, " ")-_xlfn.XLOOKUP(F33,YPP!$T:$T,YPP!$X:$X, " ") -> #VALUE! | I33: =H33*-1 -> #VALUE! | K33: =_xlfn.XLOOKUP(L33,Teams!$A:$A,Teams!$B:$B, " ") -> Cleveland Browns | L33: Cleveland | M33: =_xlfn.XLOOKUP(K33,YPP!$A:$A,YPP!$P:$P, " ")-_xlfn.XLOOKUP(K33,YPP!$T:$T,YPP!$Z:$Z, " ") -> #VALUE! | N33: =M33*-1 -> #VALUE! | P33: =_xlfn.XLOOKUP(Q33,Teams!$A:$A,Teams!$B:$B, " ") -> Cleveland Browns | Q33: Cleveland | R33: =_xlfn.XLOOKUP(P33,YPP!$A:$A,YPP!$Q:$Q, " ")-_xlfn.XLOOKUP(P33,YPP!$T:$T,YPP!$AA:$AA, " ") -> #VALUE! | S33: =R33*-1 -> #VALUE!

Sheet Self PR
A1: Rank | B1: Team | C1: PR | R1: Range
A2: 1 | B2: #VALUE! | C2: 0.85 | D2: =$R$2*C2 -> 17.85 | R2: 21
A3: 2 | B3: #VALUE! | C3: 0.83 | D3: =$R$2*C3 -> 17.43
A4: 3 | B4: #VALUE! | C4: 0.82 | D4: =$R$2*C4 -> 17.22
A5: 4 | B5: #VALUE! | C5: 0.79 | D5: =$R$2*C5 -> 16.59
A6: 5 | B6: #VALUE! | C6: 0.74 | D6: =$R$2*C6 -> 15.54
A7: 6 | B7: #VALUE! | C7: 0.73 | D7: =$R$2*C7 -> 15.33
A8: 7 | B8: #VALUE! | C8: 0.72 | D8: =$R$2*C8 -> 15.12
A9: 8 | B9: #VALUE! | C9: 0.69 | D9: =$R$2*C9 -> 14.49
A10: 9 | B10: #VALUE! | C10: 0.68 | D10: =$R$2*C10 -> 14.28
A11: 10 | B11: #VALUE! | C11: 0.66 | D11: =$R$2*C11 -> 13.86
A12: 11 | B12: #VALUE! | C12: 0.65 | D12: =$R$2*C12 -> 13.65
A13: 12 | B13: #VALUE! | C13: 0.62 | D13: =$R$2*C13 -> 13.02
A14: 13 | B14: #VALUE! | C14: 0.6 | D14: =$R$2*C14 -> 12.6
... A33: 32 | B33: #VALUE! | C33: 0.1 | D33: =$R$2*C33 -> 2.1

Sheet YPP
B1: Team | C1: 2025 | D1: Last 3 | E1: Last 1 | F1: Home | G1: Away | H1: 2024 | K1: Team | L1: 2025 | M1: Last 3 | N1: Last 1 | O1: Home | P1: Away | Q1: 2024
A2: =_xlfn.XLOOKUP(B2,Teams!$A$2:$A$33,Teams!$B$2:$B$33, " ") -> Pittsburgh Steelers | B2: Pittsburgh | C2: 11.7 | D2: 11.1 | E2: 10.1 | F2: 11.6 | G2: 11.7 | H2: 14.5 | J2: =_xlfn.XLOOKUP(K2,Teams!$A$2:$A$33,Teams!$B$2:$B$33, " ") -> Los Angeles Rams | K2: LA Rams | L2: 18.8 | M2: 18.7 | N2: 21.8 | O2: 19.6 | P2: 18.0 | Q2: 15.7
A3: =_xlfn.XLOOKUP(B3,Teams!$A$2:$A$33,Teams!$B$2:$B$33, " ") -> Indianapolis Colts | B3: Indianapolis | C3: 12.4 | D3: 14.7 | E3: 16.7 | F3: 11.6 | G3: 13.2 | H3: 15.1 | J3: =_xlfn.XLOOKUP(K3,Teams!$A$2:$A$33,Teams!$B$2:$B$33, " ") -> Kansas City Chiefs | K3: Kansas City | L3: 16.4 | M3: 17.6 | N3: 15.5 | O3: 19.2 | P3: 14.9 | Q3: 15.9
A4: =_xlfn.XLOOKUP(B4,Teams!$A$2:$A$33,Teams!$B$2:$B$33, " ") -> Seattle Seahawks | B4: Seattle | C4: 12.4 | D4: 11.9 | E4: 21.8 | F4: 10.4 | G4: 14.9 | H4: 15.1 | J4: =_xlfn.XLOOKUP(K4,Teams!$A$2:$A$33,Teams!$B$2:$B$33, " ") -> Philadelphia Eagles | K4: Philadelphia | L4: 16.3 | M4: 22.9 | N4: 35.2 | O4: 16.5 | P4: 16.0 | Q4: 16
A5: =_xlfn.XLOOKUP(B5,Teams!$A$2:$A$33,Teams!$B$2:$B$33, " ") -> Detroit Lions | B5: Detroit | C5: 12.6 | D5: 15.2 | E5: 35.2 | F5: 11.0 | G5: 13.9 | H5: 12.6 | J5: =_xlfn.XLOOKUP(K5,Teams!$A$2:$A$33,Teams!$B$2:$B$33, " ") -> New England Patriots | K5: New England | L5: 16.1 | M5: 15.1 | N5: 17.5 | O5: 16.0 | P5: 16.1 | Q5: 14
A6: =_xlfn.XLOOKUP(B6,Teams!$A$2:$A$33,Teams!$B$2:$B$33, " ") -> Baltimore Ravens | B6: Baltimore | C6: 12.8 | D6: 12.9 | E6: 15.3 | F6: 12.4 | G6: 13.1 | H6: 14.2 | J6: =_xlfn.XLOOKUP(K6,Teams!$A$2:$A$33,Teams!$B$2:$B$33, " ") -> Indianapolis Colts | K6: Indianapolis | L6: 15.9 | M6: 13.0 | N6: 11.6 | O6: 18.9 | P6: 13.9 | Q6: 14.4
A7: =_xlfn.XLOOKUP(B7,Teams!$A$2:$A$33,Teams!$B$2:$B$33, " ") -> Dallas Cowboys | B7: Dallas | C7: 12.8 | D7: 14.2 | E7: 11.5 | F7: 11.7 | G7: 13.7 | H7: 15.9 | J7: =_xlfn.XLOOKUP(K7,Teams!$A$2:$A$33,Teams!$B$2:$B$33, " ") -> Pittsburgh Steelers | K7: Pittsburgh | L7: 15.9 | M7: 17.2 | N7: 24.8 | O7: 16.5 | P7: 15.4 | Q7: 16
A8: =_xlfn.XLOOKUP(B8,Teams!$A$2:$A$33,Teams!$B$2:$B$33, " ") -> Philadelphia Eagles | B8: Philadelphia | C8: 12.8 | D8: 15.5 | E8: 17.0 | F8: 12.4 | G8: 13.3 | H8: 12.6 | J8: =_xlfn.XLOOKUP(K8,Teams!$A$2:$A$33,Teams!$B$2:$B$33, " ") -> Houston Texans | K8: Houston | L8: 15.8 | M8: 11.9 | N8: 17.6 | O8: 15.1 | P8: 16.5 | Q8: 14.3
A9: =_xlfn.XLOOKUP(B9,Teams!$A$2:$A$33,Teams!$B$2:$B$33, " ") -> Tampa Bay Buccaneers | B9: Tampa Bay | C9: 13.2 | D9: 12.2 | E9: 11.5 | F9: 13.5 | G9: 12.9 | H9: 13.6 | J9: =_xlfn.XLOOKUP(K9,Teams!$A$2:$A$33,Teams!$B$2:$B$33, " ") -> Denver Broncos | K9: Denver | L9: 15.7 | M9: 18.7 | N9: 16.4 | O9: 15.6 | P9: 15.8 | Q9: 17.1
A10: =_xlfn.XLOOKUP(B10,Teams!$A$2:$A$33,Teams!$B$2:$B$33, " ") -> Buffalo Bills | B10: Buffalo | C10: 13.3 | D10: 14.0 | E10: 9.4 | F10: 12.3 | G10: 15.3 | H10: 11.8 | J10: =_xlfn.XLOOKUP(K10,Teams!$A$2:$A$33,Teams!$B$2:$B$33, " ") -> Seattle Seahawks | K10: Seattle | L10: 15.6 | M10: 15.3 | N10: 11.9 | O10: 15.4 | P10: 15.9 | Q10: 15.4
A11: =_xlfn.XLOOKUP(B11,Teams!$A$2:$A$33,Teams!$B$2:$B$33, " ") -> Los Angeles Rams | B11: LA Rams | C11: 13.3 | D11: 11.2 | E11: 11.9 | F11: 16.0 | G11: 11.2 | H11: 15.2 | J11: =_xlfn.XLOOKUP(K11,Teams!$A$2:$A$33,Teams!$B$2:$B$33, " ") -> San Francisco 49ers | K11: San Francisco | L11: 15.4 | M11: 13.5 | N11: 22.2 | O11: 13.7 | P11: 16.4 | Q11: 12.4
A12: =_xlfn.XLOOKUP(B12,Teams!$A$2:$A$33,Teams!$B$2:$B$33, " ") -> New England Patriots | B12: New England | C12: 13.4 | D12: 13.9 | E12: 12.4 | F12: 13.8 | G12: 13.0 | H12: 17.2 | J12: =_xlfn.XLOOKUP(K12,Teams!$A$2:$A$33,Teams!$B$2:$B$33, " ") -> Green Bay Packers | K12: Green Bay | L12: 14.9 | M12: 19.5 | N12: 16.8 | O12: 17.4 | P12: 13.4 | Q12: 15.7
A13: =_xlfn.XLOOKUP(B13,Teams!$A$2:$A$33,Teams!$B$2:$B$33, " ") -> New York Jets | B13: NY Jets | C13: 13.5 | D13: 11.5 | E13: 17.5 | F13: 13.6 | G13: 13.4 | H13: 15.6 | J13: =_xlfn.XLOOKUP(K13,Teams!$A$2:$A$33,Teams!$B$2:$B$33, " ") -> Carolina Panthers | K13: Carolina | L13: 14.4 | M13: 19.4 | N13: 12.9 | O13: 15.5 | P13: 13.6 | Q13: 12.9
... A15: =_xlfn.XLOOKUP(B15,Teams!$A$2:$A$33,Teams!$B$2:$B$33, " ") -> Minnesota Vikings | B15: Minnesota | C15: 13.6 | D15: 14.1 | E15: 15.6 | F15: 14.0 | G15: 13.2 | H15: 14 | J15: =_xlfn.XLOOKUP(K15,Teams!$A$2:$A$33,Teams!$B$2:$B$33, " ") -> Jacksonville Jaguars | K15: Jacksonville | L15: 14.3 | M15: 12.4 | N15: 22.5 | O15: 20.0 | P15: 11.5 | Q15: 15.2
A16: =_xlfn.XLOOKUP(B16,Teams!$A$2:$A$33,Teams!$B$2:$B$33, " ") -> Jacksonville Jaguars | B16: Jacksonville | C16: 13.6 | D16: 9.8 | E16: 9.9 | F16: 13.3 | G16: 14.0 | H16: 16.3 | J16: =_xlfn.XLOOKUP(K16,Teams!$A$2:$A$33,Teams!$B$2:$B$33, " ") -> Miami Dolphins | K16: Miami | L16: 14.3 | M16: 20.2 | N16: 29.2 | O16: 15.0 | P16: 13.8 | Q16: 14.7 | AB16: pit | AC16: =10.5-12.5 -> -2
A17: =_xlfn.XLOOKUP(B17,Teams!$A$2:$A$33,Teams!$B$2:$B$33, " ") -> Green Bay Packers | B17: Green Bay | C17: 14.3 | D17: 19.7 | E17: 11.0 | F17: 16.9 | G17: 12.5 | H17: 14.1 | J17: =_xlfn.XLOOKUP(K17,Teams!$A$2:$A$33,Teams!$B$2:$B$33, " ") -> Baltimore Ravens | K17: Baltimore | L17: 14.1 | M17: 21.6 | N17: 11.7 | O17: 13.5 | P17: 14.8 | Q17: 15.1 | AB17: new | AC17: =14.5-15.9 -> -1.4
A18: =_xlfn.XLOOKUP(B18,Teams!$A$2:$A$33,Teams!$B$2:$B$33, " ") -> Kansas City Chiefs | B18: Kansas City | C18: 14.3 | D18: 15.4 | E18: 16.4 | F18: 13.3 | G18: 15.7 | H18: 13.9 | J18: =_xlfn.XLOOKUP(K18,Teams!$A$2:$A$33,Teams!$B$2:$B$33, " ") -> Buffalo Bills | K18: Buffalo | L18: 14.1 | M18: 12.6 | N18: 11.5 | O18: 12.9 | P18: 16.6 | Q18: 15.8
A19: =_xlfn.XLOOKUP(B19,Teams!$A$2:$A$33,Teams!$B$2:$B$33, " ") -> Denver Broncos | B19: Denver | C19: 14.4 | D19: 16.7 | E19: 15.5 | F19: 14.2 | G19: 14.6 | H19: 13.3 | J19: =_xlfn.XLOOKUP(K19,Teams!$A$2:$A$33,Teams!$B$2:$B$33, " ") -> Chicago Bears | K19: Chicago | L19: 13.8 | M19: 15.1 | N19: 15.6 | O19: 17.8 | P19: 12.2 | Q19: 16.3
A20: =_xlfn.XLOOKUP(B20,Teams!$A$2:$A$33,Teams!$B$2:$B$33, " ") -> Chicago Bears | B20: Chicago | C20: 14.5 | D20: 14.3 | E20: 16.8 | F20: 14.1 | G20: 14.8 | H20: 15.5 | J20: =_xlfn.XLOOKUP(K20,Teams!$A$2:$A$33,Teams!$B$2:$B$33, " ") -> New York Giants | K20: NY Giants | L20: 13.8 | M20: 12.6 | N20: 11.0 | O20: 14.1 | P20: 13.6 | Q20: 14.2
A21: =_xlfn.XLOOKUP(B21,Teams!$A$2:$A$33,Teams!$B$2:$B$33, " ") -> Miami Dolphins | B21: Miami | C21: 14.6 | D21: 19.5 | E21: 19.4 | F21: 14.5 | G21: 14.7 | H21: 16 | J21: =_xlfn.XLOOKUP(K21,Teams!$A$2:$A$33,Teams!$B$2:$B$33, " ") -> Minnesota Vikings | K21: Minnesota | L21: 13.7 | M21: 13.5 | N21: 16.8 | O21: 14.1 | P21: 13.3 | Q21: 16.7
A22: =_xlfn.XLOOKUP(B22,Teams!$A$2:$A$33,Teams!$B$2:$B$33, " ") -> San Francisco 49ers | B22: San Francisco | C22: 14.7 | D22: 10.4 | E22: 6.9 | F22: 17.6 | G22: 13.4 | H22: 16.4 | J22: =_xlfn.XLOOKUP(K22,Teams!$A$2:$A$33,Teams!$B$2:$B$33, " ") -> Tampa Bay Buccaneers | K22: Tampa Bay | L22: 13.7 | M22: 15.0 | N22: 9.4 | O22: 12.0 | P22: 14.9 | Q22: 15.1
A23: =_xlfn.XLOOKUP(B23,Teams!$A$2:$A$33,Teams!$B$2:$B$33, " ") -> Arizona Cardinals | B23: Arizona | C23: 14.9 | D23: 16.4 | E23: 22.2 | F23: 15.3 | G23: 14.5 | H23: 15.2 | J23: =_xlfn.XLOOKUP(K23,Teams!$A$2:$A$33,Teams!$B$2:$B$33, " ") -> Atlanta Falcons | K23: Atlanta | L23: 13.7 | M23: 15.7 | N23: 16.2 | O23: 13.0 | P23: 14.4 | Q23: 13.9
A24: =_xlfn.XLOOKUP(B24,Teams!$A$2:$A$33,Teams!$B$2:$B$33, " ") -> Houston Texans | B24: Houston | C24: 15.0 | D24: 14.9 | E24: 19.7 | F24: 14.5 | G24: 15.5 | H24: 14.8 | J24: =_xlfn.XLOOKUP(K24,Teams!$A$2:$A$33,Teams!$B$2:$B$33, " ") -> Detroit Lions | K24: Detroit | L24: 13.5 | M24: 12.6 | N24: 17.0 | O24: 16.4 | P24: 12.2 | Q24: 16.3
A25: =_xlfn.XLOOKUP(B25,Teams!$A$2:$A$33,Teams!$B$2:$B$33, " ") -> Washington Commanders | B25: Washington | C25: 15.4 | D25: 19.5 | E25: 29.2 | F25: 14.3 | G25: 16.6 | H25: 13 | J25: =_xlfn.XLOOKUP(K25,Teams!$A$2:$A$33,Teams!$B$2:$B$33, " ") -> Los Angeles Chargers | K25: LA Chargers | L25: 13.2 | M25: 11.9 | N25: 9.9 | O25: 13.7 | P25: 12.8 | Q25: 17.8
A26: =_xlfn.XLOOKUP(B26,Teams!$A$2:$A$33,Teams!$B$2:$B$33, " ") -> New York Giants | B26: NY Giants | C26: 15.5 | D26: 16.6 | E26: 16.8 | F26: 14.2 | G26: 16.6 | H26: 18.4 | J26: =_xlfn.XLOOKUP(K26,Teams!$A$2:$A$33,Teams!$B$2:$B$33, " ") -> Arizona Cardinals | K26: Arizona | L26: 13.0 | M26: 9.7 | N26: 6.9 | O26: 11.9 | P26: 14.3 | Q26: 15.4
A27: =_xlfn.XLOOKUP(B27,Teams!$A$2:$A$33,Teams!$B$2:$B$33, " ") -> Los Angeles Chargers | B27: LA Chargers | C27: 15.5 | D27: 13.7 | E27: 22.5 | F27: 15.9 | G27: 15.2 | H27: 13.9 | J27: =_xlfn.XLOOKUP(K27,Teams!$A$2:$A$33,Teams!$B$2:$B$33, " ") -> Dallas Cowboys | K27: Dallas | L27: 13.0 | M27: 11.5 | N27: 14.8 | O27: 13.3 | P27: 12.8 | Q27: 12.9
A28: =_xlfn.XLOOKUP(B28,Teams!$A$2:$A$33,Teams!$B$2:$B$33, " ") -> Cleveland Browns | B28: Cleveland | C28: 15.9 | D28: 13.8 | E28: 11.7 | F28: 12.4 | G28: 19.0 | H28: 19.8 | J28: =_xlfn.XLOOKUP(K28,Teams!$A$2:$A$33,Teams!$B$2:$B$33, " ") -> Las Vegas Raiders | K28: Las Vegas | L28: 12.9 | M28: 13.3 | N28: 11.5 | O28: 13.2 | P28: 12.6 | Q28: 13
A29: =_xlfn.XLOOKUP(B29,Teams!$A$2:$A$33,Teams!$B$2:$B$33, " ") -> Carolina Panthers | B29: Carolina | C29: 16.7 | D29: 17.5 | E29: 16.2 | F29: 14.3 | G29: 19.1 | H29: 14.9 | J29: =_xlfn.XLOOKUP(K29,Teams!$A$2:$A$33,Teams!$B$2:$B$33, " ") -> Tennessee Titans | K29: Tennessee | L29: 12.9 | M29: 13.3 | N29: 19.7 | O29: 12.5 | P29: 13.4 | Q29: 11.5
... A33: =_xlfn.XLOOKUP(B33,Teams!$A$2:$A$33,Teams!$B$2:$B$33, " ") -> New Orleans Saints | B33: New Orleans | C33: 19.2 | D33: 29.6 | E33: 22.8 | F33: 18.6 | G33: 19.8 | H33: 16.1 | J33: =_xlfn.XLOOKUP(K33,Teams!$A$2:$A$33,Teams!$B$2:$B$33, " ") -> Cleveland Browns | K33: Cleveland | L33: 11.7 | M33: 11.5 | N33: 15.3 | O33: 16.8 | P33: 10.1 | Q33: 13.4

Sheet Offense Data 2025
A1: Team Offense Table
A2: Rk | B2: Tm | C2: G | D2: PF | E2: Yds | F2: Ply | G2: Y/P | H2: TO | I2: FL | J2: 1stD | K2: Cmp | L2: Att | M2: Yds_1 | N2: TD | O2: Int | P2: NY/A | Q2: 1stD_2 | R2: Att_3 | S2: Yds_4 | T2: TD_5 | U2: Y/A | V2: 1stD_6 | W2: Pen | X2: Yds_7 | Y2: 1stPy | Z2: Sc% | AA2: TO% | AB2: EXP
A3: 1 | B3: Indianapolis Colts | C3: 10 | D3: 321 | E3: 3969 | F3: 619 | G3: 6.4 | H3: 12 | I3: 5 | J3: 237 | K3: 224 | L3: 324 | M3: 2516 | N3: 15 | O3: 7 | P3: 7.3 | Q3: 131 | R3: 274 | S3: 1453 | T3: 22 | U3: 5.3 | V3: 87 | W3: 62 | X3: 524 | Y3: 19 | Z3: 56.7 | AA3: 11.3 | AB3: 152.94
A4: 2 | B4: Dallas Cowboys | C4: 10 | D4: 296 | E4: 3787 | F4: 645 | G4: 5.9 | H4: 12 | I4: 5 | J4: 231 | K4: 259 | L4: 371 | M4: 2587 | N4: 22 | O4: 7 | P4: 6.7 | Q4: 135 | R4: 258 | S4: 1200 | T4: 10 | U4: 4.7 | V4: 69 | W4: 79 | X4: 660 | Y4: 27 | Z4: 47.4 | AA4: 11.6 | AB4: 116.14
A5: 3 | B5: Seattle Seahawks | C5: 10 | D5: 294 | E5: 3658 | F5: 593 | G5: 6.2 | H5: 20 | I5: 9 | J5: 205 | K5: 193 | L5: 276 | M5: 2494 | N5: 17 | O5: 11 | P5: 8.7 | Q5: 112 | R5: 307 | S5: 1164 | T5: 12 | U5: 3.8 | V5: 69 | W5: 60 | X5: 500 | Y5: 24 | Z5: 44.5 | AA5: 17.3 | AB5: 57.66
A6: 4 | B6: Buffalo Bills | C6: 10 | D6: 292 | E6: 3874 | F6: 620 | G6: 6.2 | H6: 12 | I6: 5 | J6: 224 | K6: 207 | L6: 299 | M6: 2398 | N6: 18 | O6: 7 | P6: 7.5 | Q6: 121 | R6: 301 | S6: 1476 | T6: 19 | U6: 4.9 | V6: 79 | W6: 68 | X6: 563 | Y6: 24 | Z6: 47.2 | AA6: 10.4 | AB6: 120.5
A7: 5 | B7: New England Patriots | C7: 11 | D7: 292 | E7: 3927 | F7: 674 | G7: 5.8 | H7: 12 | I7: 7 | J7: 225 | K7: 231 | L7: 322 | M7: 2685 | N7: 20 | O7: 5 | P7: 7.5 | Q7: 133 | R7: 316 | S7: 1242 | T7: 12 | U7: 3.9 | V7: 74 | W7: 74 | X7: 585 | Y7: 18 | Z7: 42 | AA7: 10.7 | AB7: 96.52
A8: 6 | B8: Detroit Lions | C8: 10 | D8: 292 | E8: 3669 | F8: 614 | G8: 6 | H8: 7 | I8: 3 | J8: 197 | K8: 217 | L8: 313 | M8: 2368 | N8: 22 | O8: 4 | P8: 7.1 | Q8: 124 | R8: 281 | S8: 1301 | T8: 13 | U8: 4.6 | V8: 65 | W8: 60 | X8: 440 | Y8: 8 | Z8: 43.2 | AA8: 6.3 | AB8: 94.97
A9: 7 | B9: Los Angeles Rams | C9: 10 | D9: 272 | E9: 3609 | F9: 623 | G9: 5.8 | H9: 8 | I9: 6 | J9: 227 | K9: 223 | L9: 339 | M9: 2469 | N9: 27 | O9: 2 | P9: 7 | Q9: 132 | R9: 270 | S9: 1140 | T9: 8 | U9: 4.2 | V9: 69 | W9: 47 | X9: 389 | Y9: 26 | Z9: 42.5 | AA9: 7.5 | AB9: 115.03
A10: 8 | B10: San Francisco 49ers | C10: 11 | D10: 261 | E10: 3843 | F10: 702 | G10: 5.5 | H10: 15 | I10: 5 | J10: 240 | K10: 268 | L10: 388 | M10: 2800 | N10: 20 | O10: 10 | P10: 6.9 | Q10: 152 | R10: 295 | S10: 1043 | T10: 8 | U10: 3.5 | V10: 71 | W10: 62 | X10: 482 | Y10: 17 | Z10: 45.1 | AA10: 13.3 | AB10: 59.47
A11: 9 | B11: Chicago Bears | C11: 10 | D11: 258 | E11: 3738 | F11: 649 | G11: 5.8 | H11: 6 | I11: 2 | J11: 207 | K11: 198 | L11: 331 | M11: 2272 | N11: 14 | O11: 4 | P11: 6.5 | Q11: 109 | R11: 302 | S11: 1466 | T11: 12 | U11: 4.9 | V11: 84 | W11: 80 | X11: 641 | Y11: 14 | Z11: 45 | AA11: 5.4 | AB11: 56.93
A12: 10 | B12: Denver Broncos | C12: 11 | D12: 257 | E12: 3688 | F12: 692 | G12: 5.3 | H12: 12 | I12: 4 | J12: 207 | K12: 237 | L12: 388 | M12: 2343 | N12: 18 | O12: 8 | P12: 5.8 | Q12: 118 | R12: 291 | S12: 1345 | T12: 11 | U12: 4.6 | V12: 69 | W12: 93 | X12: 883 | Y12: 20 | Z12: 35.9 | AA12: 7.8 | AB12: 42.74
A13: 11 | B13: Kansas City Chiefs | C13: 10 | D13: 254 | E13: 3642 | F13: 640 | G13: 5.7 | H13: 6 | I13: 0 | J13: 224 | K13: 233 | L13: 361 | M13: 2489 | N13: 18 | O13: 6 | P13: 6.5 | Q13: 130 | R13: 259 | S13: 1153 | T13: 12 | U13: 4.5 | V13: 78 | W13: 69 | X13: 577 | Y13: 16 | Z13: 48.9 | AA13: 6.4 | AB13: 118.29
A14: 12 | B14: Tampa Bay Buccaneers | C14: 10 | D14: 252 | E14: 3322 | F14: 624 | G14: 5.3 | H14: 7 | I14: 4 | J14: 196 | K14: 216 | L14: 340 | M14: 2222 | N14: 17 | O14: 3 | P14: 6.2 | Q14: 106 | R14: 264 | S14: 1100 | T14: 9 | U14: 4.2 | V14: 67 | W14: 58 | X14: 467 | Y14: 23 | Z14: 41.8 | AA14: 6.4 | AB14: 41.14
... A34: 32 | B34: Tennessee Titans | C34: 10 | D34: 143 | E34: 2425 | F34: 573 | G34: 4.2 | H34: 14 | I34: 8 | J34: 151 | K34: 194 | L34: 332 | M34: 1636 | N34: 6 | O34: 6 | P34: 4.4 | Q34: 98 | R34: 200 | S34: 789 | T34: 3 | U34: 3.9 | V34: 40 | W34: 70 | X34: 536 | Y34: 13 | Z34: 27.1 | AA34: 13.1 | AB34: -89.05
B35: Avg Team | D35: 237.9 | E35: 3370.9 | F35: 627.7 | G35: 5.4 | H35: 11.8 | I35: 4.8 | J35: 200.7 | K35: 216.1 | L35: 332.7 | M35: 2187.7 | N35: 15.8 | O35: 7 | P35: 6.1 | Q35: 112.2 | R35: 271 | S35: 1183.2 | T35: 9.6 | U35: 4.4 | V35: 68.6 | W35: 69 | X35: 554.1 | Y35: 19.8 | Z35: 39.6 | AA35: 10.3 | AB35: 39.4
B36: League Total | D36: 7614 | E36: 107869 | F36: 20086 | G36: 5.4 | H36: 376 | I36: 153 | J36: 6421 | K36: 6914 | L36: 10647 | M36: 70007 | N36: 507 | O36: 223 | P36: 6.1 | Q36: 3591 | R36: 8660 | S36: 37862 | T36: 308 | U36: 4.4 | V36: 2195 | W36: 2208 | X36: 17732 | Y36: 635 | Z36: 39.6 | AA36: 10.3
B37: Avg Tm/G | D37: 23.2 | E37: 328.9 | F37: 61.2 | G37: 5.4 | H37: 1.1 | I37: 0.5 | J37: 19.6 | K37: 21.1 | L37: 32.5 | M37: 213.4 | N37: 1.5 | O37: 0.7 | P37: 6.1 | Q37: 10.9 | R37: 26 | S37: 115.4 | T37: 0.9 | U37: 4.4 | V37: 6.7 | W37: 6.7 | X37: 54.1 | Y37: 1.9 | Z37: 39.6 | AA37: 10.3
A40: Passing Offense Table
A41: Rk | B41: Tm | C41: G | D41: Cmp | E41: Att | F41: Cmp% | G41: Yds | H41: TD | I41: TD% | J41: Int | K41: Int% | L41: Lng | M41: Y/A | N41: AY/A | O41: Y/C | P41: Y/G | Q41: Rate | R41: Sk | S41: Yds_1 | T41: Sk% | U41: NY/A | V41: ANY/A | W41: 4QC | X41: GWD | Y41: EXP
A42: 1 | B42: San Francisco 49ers | C42: 11 | D42: 268 | E42: 388 | F42: 69.1 | G42: 2800 | H42: 20 | I42: 5.2 | J42: 10 | K42: 2.6 | L42: 56 | M42: 7.6 | N42: 7.4 | O42: 11 | P42: 254.5 | Q42: 97.6 | R42: 19 | S42: 137 | T42: 4.7 | U42: 6.9 | V42: 6.8 | W42: 2 | X42: 3 | Y42: 82.81
A43: 2 | B43: New England Patriots | C43: 11 | D43: 231 | E43: 322 | F43: 71.7 | G43: 2685 | H43: 20 | I43: 6.2 | J43: 5 | K43: 1.6 | L43: 72 | M43: 8.8 | N43: 9.4 | O43: 12.3 | P43: 244.1 | Q43: 113 | R43: 36 | S43: 163 | T43: 10.1 | U43: 7.5 | V43: 8 | W43: 0 | X43: 1 | Y43: 128.75
